Workbook

Sheet DECLARACIONES SALUD
A1: Fecha | B1: Agente | C1: Patología | D1: Tipo | E1: Resultado | F1: Comentario / Acción | G1: Buscador
A2: 45323 | B2: Bianca | C2: Glomerulo esclerosis renal con HTA y proteinuria Hace 1 año | D2: Autoinmunes, reumatológicas, de la sangre, infecciosas o dermatológicas | E2: No asegurable | G2: =IF(IFERROR(FIND(LOWER('Buscador Patologías'!$P$3),C2,1),0)<>0,1,IF(IFERROR(FIND('Buscador Patologías'!$B$3,C2,1),0)=0,0,1)) -> 1
A3: 45323 | B3: Bianca | C3: Sertralina antidepresivo + secuelas de hernia discal | D3: Traumatología | E3: No asegurable | G3: =IF(IFERROR(FIND(LOWER('Buscador Patologías'!$P$3),C3,1),0)<>0,1,IF(IFERROR(FIND('Buscador Patologías'!$B$3,C3,1),0)=0,0,1)) -> 0
A4: 45323 | B4: Lorena | C4: Autismo, Síndrome de Asperger | D4: Psiquiátrica | E4: Exclusión | F4: Necesario informe médico para valorar. | G4: =IF(IFERROR(FIND(LOWER('Buscador Patologías'!$P$3),C4,1),0)<>0,1,IF(IFERROR(FIND('Buscador Patologías'!$B$3,C4,1),0)=0,0,1)) -> 0
A5: 45323 | B5: Belén | C5: Artritis Reumatoide | D5: Autoinmunes, reumatológicas, de la sangre, infecciosas o dermatológicas | E5: Exclusión | F5: 90% de casos son Rechazo directo. Necesario informe médico para valorar. | G5: =IF(IFERROR(FIND(LOWER('Buscador Patologías'!$P$3),C5,1),0)<>0,1,IF(IFERROR(FIND('Buscador Patologías'!$B$3,C5,1),0)=0,0,1)) -> 0
A6: 45323 | B6: Belén | C6: Stent. Endoprótesis vasculares (endoprotesis, stem, sten, marcapasos, stent, estent, esten, wallstent) | D6: Cardíaca | E6: No asegurable | F6: Rechazo directo. | G6: =IF(IFERROR(FIND(LOWER('Buscador Patologías'!$P$3),C6,1),0)<>0,1,IF(IFERROR(FIND('Buscador Patologías'!$B$3,C6,1),0)=0,0,1)) -> 0
A7: 45323 | B7: Pilar | C7: Altura 170 cm, Peso 93 Kg, Resultado Índice de masa corporal (IMC) = 32,2 | D7: Obesidad | E7: Exclusión | F7: Excluidos los ingresos, y procedimientos para el estudio diagnóstico y/o tratamiento médico, endoscópicoo quirúrgico de la obesidad. Si en el futuro baja peso se puede solicitar una nueva selección de riesgo aportando nuevo cuestionario e informes sobre la exclusión. No hay un tiempo específico, lo puede solicitar incluso el año que viene. Dicho esto, no significa que una vez que lo aporte se le quite la exclusión dependerá de la valoración del departamento médico. | G7: =IF(IFERROR(FIND(LOWER('Buscador Patologías'!$P$3),C7,1),0)<>0,1,IF(IFERROR(FIND('Buscador Patologías'!$B$3,C7,1),0)=0,0,1)) -> 0
A8: 45325 | B8: Pilar | C8: Diabetes tipo 1 (se pincha insulina, diabético, diabética, diabete) | D8: Autoinmunes, reumatológicas, de la sangre, infecciosas o dermatológicas | E8: No asegurable | F8: Rechazo directo. | G8: =IF(IFERROR(FIND(LOWER('Buscador Patologías'!$P$3),C8,1),0)<>0,1,IF(IFERROR(FIND('Buscador Patologías'!$B$3,C8,1),0)=0,0,1)) -> 0
A9: 45323 | B9: Héctor | C9: SENIORS. Diabetes Tipo 1 (se pincha insulina, diabético, diabética, diabete) | D9: Autoinmunes, reumatológicas, de la sangre, infecciosas o dermatológicas | E9: No asegurable | F9: Necesario informe médico para valorar. | G9: =IF(IFERROR(FIND(LOWER('Buscador Patologías'!$P$3),C9,1),0)<>0,1,IF(IFERROR(FIND('Buscador Patologías'!$B$3,C9,1),0)=0,0,1)) -> 0
A10: 45323 | B10: Héctor | C10: Parkinson | D10: Neurología | E10: No asegurable | F10: Enfermedad degenerativa. Rechazo directo. | G10: =IF(IFERROR(FIND(LOWER('Buscador Patologías'!$P$3),C10,1),0)<>0,1,IF(IFERROR(FIND('Buscador Patologías'!$B$3,C10,1),0)=0,0,1)) -> 0
A11: 45323 | B11: Lorena | C11: SENIORS. Diabetes Tipo 2 (tratamiento con pastillas) | D11: Autoinmunes, reumatológicas, de la sangre, infecciosas o dermatológicas | E11: Aceptado | F11: No es necesario aportar informe, pasa limpia. | G11: =IF(IFERROR(FIND(LOWER('Buscador Patologías'!$P$3),C11,1),0)<>0,1,IF(IFERROR(FIND('Buscador Patologías'!$B$3,C11,1),0)=0,0,1)) -> 0
A12: 45324 | B12: Pilar | C12: Hiperuricemia (gota), anemia ferropénica. deficit B12, diabetes,... | D12: Autoinmunes, reumatológicas, de la sangre, infecciosas o dermatológicas | E12: No asegurable | F12: Necesario informe médico para valorar. Rechazada. | G12: =IF(IFERROR(FIND(LOWER('Buscador Patologías'!$P$3),C12,1),0)<>0,1,IF(IFERROR(FIND('Buscador Patologías'!$B$3,C12,1),0)=0,0,1)) -> 0
A13: 45325 | B13: Héctor | C13: Hígado grasiento diagnosticado hace más de 20 años (higado, hígado graso) | D13: Digestiva, hernias, hepatitis y páncreas | E13: No asegurable | F13: Rechazo directo. | G13: =IF(IFERROR(FIND(LOWER('Buscador Patologías'!$P$3),C13,1),0)<>0,1,IF(IFERROR(FIND('Buscador Patologías'!$B$3,C13,1),0)=0,0,1)) -> 0
A14: 45323 | B14: Yésica | C14: Operación de femur hace más de 40 años (fémur) (pierna, rodilla, cadera). | D14: Traumatología | E14: Exclusión | F14: 2-EXCLUSIÓN RETIRADA, SUSTITUCIÓN Y/O RECAMBIO DEL MATERIAL DE OSTEOSÍNTESIS FEMUR INTERVENIDO (MEDIOS DE DIAGNÓSTICO, TRATAMIENTOS E INGRESOS), ASÍ COMO POR SUS COMPLICACIONES, CONSECUENCIAS Y/O SECUELAS. Necesario firmar la exclusión para poder asegurar. Tardarán varios días en enviarte la carta de exclusión, paciencia. | G14: =IF(IFERROR(FIND(LOWER('Buscador Patologías'!$P$3),C14,1),0)<>0,1,IF(IFERROR(FIND('Buscador Patologías'!$B$3,C14,1),0)=0,0,1)) -> 0
A15: 45323 | B15: Pilar | C15: Desprendimiento de retina. | D15: Oftalmología | E15: Exclusión | F15: EXCLUSION DE LOS MEDIOS DE DIAGNOSTICO , TRATAMIENTOS E INGRESOS RELACIONADOS CON LAS COMPLICACIONES , CONSECUENCIAS Y/O SECUELAS DE DESPRENDIMIENTO DE RETINA | G15: =IF(IFERROR(FIND(LOWER('Buscador Patologías'!$P$3),C15,1),0)<>0,1,IF(IFERROR(FIND('Buscador Patologías'!$B$3,C15,1),0)=0,0,1)) -> 0
... A21: 45352 | B21: Lorena | C21: Hipotiroidismo, tiroides, hipertiroidismo, hipotiroides, hipertiroides, sin operar toma pastillas Eutirox | D21: Sistema Endocrino y Metabólico | E21: Exclusión | F21: EXCLUSION AFECCIONES DE TIROIDES: MEDIOS DE DIAGNOSTICO , TRATAMIENTOS E INGRESOS , ASI COMO POR SUS COMPLICACIONES , CONSECUENCIAS Y/O SECUELAS | G21: =IF(IFERROR(FIND(LOWER('Buscador Patologías'!$P$3),C21,1),0)<>0,1,IF(IFERROR(FIND('Buscador Patologías'!$B$3,C21,1),0)=0,0,1)) -> 0
A22: 45352 | B22: Pilar | C22: Le han quitado miomas, (mioma) | E22: Exclusión | F22: EXCLUSION DE LOS MEDIOS DE DIAGNOSTICO , TRATAMIENTOS E INGRESOS RELACIONADOS CON LAS RECIDIVAS , COMPLICACIONES , CONSECUENCIAS Y/O SECUELAS DE TUMORES BENIGNOS DE UTERO (1) , METRORRAGIAS (2) | G22: =IF(IFERROR(FIND(LOWER('Buscador Patologías'!$P$3),C22,1),0)<>0,1,IF(IFERROR(FIND('Buscador Patologías'!$B$3,C22,1),0)=0,0,1)) -> 0
A23: 45352 | B23: Yésica | C23: Hace 10 años corte de ligamentos y menisco de la rodilla izquierda, ingresada y operada, sin secuelas en la actualidad, lleva una grapa. | D23: Traumatología | E23: Exclusión | F23: EXCLUSIÓN DE MEDIOS DIAGNÓSTICOS, TRATAMIENTO E INGRESOS RELACIONADOS CON LAS RECIDIVAS, COMPLICACIONES, CONSECUENCIAS Y/O SECUELAS DE RODILLA IZQUIERDA INTERVENIDA. | G23: =IF(IFERROR(FIND(LOWER('Buscador Patologías'!$P$3),C23,1),0)<>0,1,IF(IFERROR(FIND('Buscador Patologías'!$B$3,C23,1),0)=0,0,1)) -> 0
A24: 45352 | B24: Yésica | C24: Prótesis en las dos rodillas hace 12 años | D24: Traumatología | E24: Exclusión | F24: HISTORIAL MÉDICO COMPLETO Y ACTUALIZADO QUE INCLUYA DIAGNÓSTICOS EN VIGOR,ANTECEDENTES MÉDICO.QUIRÚRGICOS, TRATAMIENTOS, SITUACIÓN ACTUAL | G24: =IF(IFERROR(FIND(LOWER('Buscador Patologías'!$P$3),C24,1),0)<>0,1,IF(IFERROR(FIND('Buscador Patologías'!$B$3,C24,1),0)=0,0,1)) -> 0
A25: 45352 | B25: Héctor | C25: La causa de rechazo es IMC de la asegurada Rocío Hidalgo. Edad 13 años, estatura 159,5 y peso 86,5. Obesidad. IMC = 34 | D25: Obesidad | E25: No asegurable | G25: =IF(IFERROR(FIND(LOWER('Buscador Patologías'!$P$3),C25,1),0)<>0,1,IF(IFERROR(FIND('Buscador Patologías'!$B$3,C25,1),0)=0,0,1)) -> 0
A26: 45383 | B26: Yésica | C26: SENIOR operada en los dos ojos de miopia | D26: Oftalmología | E26: Aceptado | F26: Aceptado sin carencias y sin exclusiones, PASA LIMPIA. | G26: =IF(IFERROR(FIND(LOWER('Buscador Patologías'!$P$3),C26,1),0)<>0,1,IF(IFERROR(FIND('Buscador Patologías'!$B$3,C26,1),0)=0,0,1)) -> 0
A27: 45384 | B27: Yésica | C27: SENIOR diabético tipo 2, toma 2 pastillas distintas por la diabetes, | D27: Autoinmunes, reumatológicas, de la sangre, infecciosas o dermatológicas | E27: Aceptado | F27: Aceptado sin carencias y sin exclusiones, PASA LIMPIA. | G27: =IF(IFERROR(FIND(LOWER('Buscador Patologías'!$P$3),C27,1),0)<>0,1,IF(IFERROR(FIND('Buscador Patologías'!$B$3,C27,1),0)=0,0,1)) -> 0
A28: 45385 | B28: Yésica | C28: SENIOR hipertensión | D28: Cardíaca | E28: Aceptado | F28: Aceptado sin carencias y sin exclusiones, PASA LIMPIA. | G28: =IF(IFERROR(FIND(LOWER('Buscador Patologías'!$P$3),C28,1),0)<>0,1,IF(IFERROR(FIND('Buscador Patologías'!$B$3,C28,1),0)=0,0,1)) -> 0
A29: 45386 | B29: Lorena | C29: Operada de tiroides, toma Eutirox. Debe aportar informe médico, si no puede conseguirlo hay que hacerle una carta jurada para que declare la enfermedad que tiene y que confirme que acepta la máxima exclusíon posible. Si en un futuro aporta informe se puede mandar a Adeslas para valorarlo nuevamente. | D29: Sistema Endocrino y Metabólico | E29: Exclusión | F29: SE PRECISA INFORMACIÓN MÉDICA ACTUALIZADA SOBRE TIROIDECTOMÍA: DIAGNÓSTICO/CAUSA/MOTIVO, LOCALIZACIÓN, FECHAS, TRATAMIENTO, PRONÓSTICO Y SITUACIÓN ACTUAL | G29: =IF(IFERROR(FIND(LOWER('Buscador Patologías'!$P$3),C29,1),0)<>0,1,IF(IFERROR(FIND('Buscador Patologías'!$B$3,C29,1),0)=0,0,1)) -> 0
A30: 45385 | B30: Yésica | C30: SENIORS 80 años de edad que hace 12 años le pusieron un STENT. Pesa 68kg y mide 167cm. No tiene ningún tipo de recaída y secuela durante todos estos años. | D30: Cardíaca | E30: No asegurable | G30: =IF(IFERROR(FIND(LOWER('Buscador Patologías'!$P$3),C30,1),0)<>0,1,IF(IFERROR(FIND('Buscador Patologías'!$B$3,C30,1),0)=0,0,1)) -> 0
A31: 45386 | B31: Lorena | C31: SENIORS diabetes tipo 2 + hipertensión + operación de cadera menos de 1 año | D31: Traumatología | E31: No asegurable | G31: =IF(IFERROR(FIND(LOWER('Buscador Patologías'!$P$3),C31,1),0)<>0,1,IF(IFERROR(FIND('Buscador Patologías'!$B$3,C31,1),0)=0,0,1)) -> 0
A32: 45413 | B32: Lorena | C32: Extirpación de vesícula, le quitaron la vesícula | E32: Exclusión | G32: =IF(IFERROR(FIND(LOWER('Buscador Patologías'!$P$3),C32,1),0)<>0,1,IF(IFERROR(FIND('Buscador Patologías'!$B$3,C32,1),0)=0,0,1)) -> 0
A33: 45413 | B33: Yésica | C33: Tea leve, sin mediación, autismo, recién diagnosticado, sin tratamiento. | D33: Psiquiátrica | E33: Exclusión | F33: EXCLUSIÓN DE LOS MEDIOS DE DIAGNÓSTICO, TRATAMIENTOS E INGRESOS RELACIONADOS CON LAS COMPLICACIONES, CONSECUENCIAS Y/O SECUELAS DE TRASTORNO DEL ESPECTRO AUTISTA (TEA) | G33: =IF(IFERROR(FIND(LOWER('Buscador Patologías'!$P$3),C33,1),0)<>0,1,IF(IFERROR(FIND('Buscador Patologías'!$B$3,C33,1),0)=0,0,1)) -> 0
A34: 45413 | B34: Yésica | C34: Lleva una placa con tornillos en el radio hace 25 años | D34: Traumatología | E34: Exclusión | F34: EXCLUSION RETIRADA , SUSTITUCION Y/O RECAMBIO DEL MATERIAL DE OSTEOSINTESIS (MEDIOS DE DIAGNOSTICO , TRATAMIENTOS E INGRESOS) , ASI COMO POR SUS COMPLICACIONES , CONSECUENCIAS Y/O SECUELAS | G34: =IF(IFERROR(FIND(LOWER('Buscador Patologías'!$P$3),C34,1),0)<>0,1,IF(IFERROR(FIND('Buscador Patologías'!$B$3,C34,1),0)=0,0,1)) -> 0
A35: 45413 | B35: Lorena | C35: Meningioma pequeño | D35: Autoinmunes, reumatológicas, de la sangre, infecciosas o dermatológicas | E35: No asegurable | G35: =IF(IFERROR(FIND(LOWER('Buscador Patologías'!$P$3),C35,1),0)<>0,1,IF(IFERROR(FIND('Buscador Patologías'!$B$3,C35,1),0)=0,0,1)) -> 0
A36: 45413 | B36: Yésica | C36: Reducción de estómago en el 2018, hace 6 años. | D36: Obesidad | E36: No asegurable | F36: RECHAZO DIRECTO | G36: =IF(IFERROR(FIND(LOWER('Buscador Patologías'!$P$3),C36,1),0)<>0,1,IF(IFERROR(FIND('Buscador Patologías'!$B$3,C36,1),0)=0,0,1)) -> 0
A37: 45413 | B37: Yésica | C37: Tiene un lado de cadera operada y el otro sin operar | D37: Traumatología | E37: Exclusión | F37: NECESARIO INFORME MÉDICO DE LAS DOS CADERAS PARA CONTINUAR CON LA VALORACIÓN | G37: =IF(IFERROR(FIND(LOWER('Buscador Patologías'!$P$3),C37,1),0)<>0,1,IF(IFERROR(FIND('Buscador Patologías'!$B$3,C37,1),0)=0,0,1)) -> 0
A38: 45413 | B38: Héctor | C38: Operación de cataratas en los dos ojos | D38: Oftalmología | E38: Exclusión | F38: EXCLUSIÓN DE CATARATAS | G38: =IF(IFERROR(FIND(LOWER('Buscador Patologías'!$P$3),C38,1),0)<>0,1,IF(IFERROR(FIND('Buscador Patologías'!$B$3,C38,1),0)=0,0,1)) -> 0
A39: 45413 | B39: Héctor | C39: Operación apendicitis de niño | D39: Traumatología | E39: Aceptado | F39: PASA LIMPIA | G39: =IF(IFERROR(FIND(LOWER('Buscador Patologías'!$P$3),C39,1),0)<>0,1,IF(IFERROR(FIND('Buscador Patologías'!$B$3,C39,1),0)=0,0,1)) -> 0
A40: 45413 | B40: Héctor | C40: Vasectomia para operar en seguridad social | D40: Renal, Urológia o Ginecológica | E40: Aceptado | G40: =IF(IFERROR(FIND(LOWER('Buscador Patologías'!$P$3),C40,1),0)<>0,1,IF(IFERROR(FIND('Buscador Patologías'!$B$3,C40,1),0)=0,0,1)) -> 0
A41: 45444 | B41: Yésica | C41: Asma y Fuma medio paquete al día | D41: Respiratoria | E41: No asegurable | F41: ASMA Y FUMA RECHAZO DIRECTO | G41: =IF(IFERROR(FIND(LOWER('Buscador Patologías'!$P$3),C41,1),0)<>0,1,IF(IFERROR(FIND('Buscador Patologías'!$B$3,C41,1),0)=0,0,1)) -> 0
A42: 45444 | B42: Yésica | C42: SENIORS tensión alta, azúcar y una hernia inguinal que se la han quitado hace años | D42: Traumatología | E42: Aceptado | F42: PASA LIMPIA | G42: =IF(IFERROR(FIND(LOWER('Buscador Patologías'!$P$3),C42,1),0)<>0,1,IF(IFERROR(FIND('Buscador Patologías'!$B$3,C42,1),0)=0,0,1)) -> 0
A43: 45444 | B43: Héctor | C43: Hiperuricemia | D43: Autoinmunes, reumatológicas, de la sangre, infecciosas o dermatológicas | E43: No asegurable | F43: RECHAZO DIRECTO | G43: =IF(IFERROR(FIND(LOWER('Buscador Patologías'!$P$3),C43,1),0)<>0,1,IF(IFERROR(FIND('Buscador Patologías'!$B$3,C43,1),0)=0,0,1)) -> 0
A44: 45444 | B44: Héctor | C44: SENIORS Cirugía mayor reciente sea cual sea la edad y el estado del paciente | D44: Traumatología | E44: No asegurable | F44: RECHAZO DIRECTO | G44: =IF(IFERROR(FIND(LOWER('Buscador Patologías'!$P$3),C44,1),0)<>0,1,IF(IFERROR(FIND('Buscador Patologías'!$B$3,C44,1),0)=0,0,1)) -> 0
A45: 45444 | B45: Héctor | C45: Cirugía mayor reciente sea cual sea la edad y el estado del paciente | D45: Traumatología | E45: No asegurable | F45: RECHAZO DIRECTO | G45: =IF(IFERROR(FIND(LOWER('Buscador Patologías'!$P$3),C45,1),0)<>0,1,IF(IFERROR(FIND('Buscador Patologías'!$B$3,C45,1),0)=0,0,1)) -> 0
...

Sheet Buscador Patologías
B1: *PONER LA PRIMERA LETRA EN MAYÚSCULAS **Cada caso es diferente, Adeslas valora según edad, peso, altura, etc. ***La valoración también puede variar dependiendo del médico del Departamento de Selección de Riesgo.
B3: Esclerosis | P3: =PROPER(B3) -> Esclerosis

Sheet Datos1
A1: Fecha | B1: Agente | C1: Patología | D1: Tipo | E1: Resultado | F1: Comentario / Acción | G1: Buscador
A2: 45352 | B2: Yésica | C2: SENIORS Próstata operada hace 15 años (no es tumor, no cáncer). Cataratas operadas hace 2 años. (prostata) | D2: Renal, Urológia o Ginecológica | E2: Exclusión | F2: EXCLUSION (1) AFECCIONES DE PRÓSTATA Y (2) CATARATAS (MEDIOS DE DIAGNÓSTICO, TRATAMIENTOS E INGRESOS), ASÍ COMO POR SUS COMPLICACIONES, CONSECUENCIAS Y/O SECUELAS | G2: 1

Sheet DS ADESLAS 2013
A1: Fecha última actualización | F1: 41451
A2: APARATO RESPIRATORIO | B2: Aceptación directa | C2: Exclusión directa | D2: Denegación directa | E2: Petición de informe | F2: Características de þ
A3: Afonia | E3: þ
A4: Apneas del sueño | D4: þ
A5: Asma | C5: þ | F5: Únicamente a ingresos
A6: Bronquitis crónica | D6: þ
D7: þ
D8: þ
A9: Bronquiectasias | D9: þ
A10: Enfisema | D10: þ
A11: Neumonía | B11: þ
A12: Tuberculosis pulmonar | E12: þ | F12: Solicitar si afecta a otros órganos o sistemas
A14: CARDIO-CIRCULATORIO | B14: Aceptación directa | C14: Exclusión directa | D14: Denegación directa | E14: Petición de informe | F14: Características de þ
A15: Angina de Pecho | D15: þ
A16: Arterioesclerosis | E16: þ
A17: Defecto cardíaco congénito | E17: þ
A18: Embolias | D18: þ
A19: Flebitis | E19: þ
A20: Infarto | D20: þ
A21: Palpitaciones | E21: þ
A22: Tensión arterial elevada | E22: þ
A23: Trombosis | D23: þ
A24: Valvulopatías | E24: þ
A25: Varices (ext.inf.) | C25: þ | F25: Bilateral
A27: SISTEMA NERVIOSO | B27: Aceptación directa | C27: Exclusión directa | D27: Denegación directa | E27: Petición de informe | F27: Características de þ
A28: Accidente Cerebro Vascular | D28: þ
A29: Anorexia/Bulimia | D29: þ
A30: Ansiedad | E30: þ
A31: Apoplejía | D31: þ
A32: Demencia | D32: þ
A33: Depresiones | D33: þ
A34: Desmayos | E34: þ
A35: Epilepsia Gran Mal | D35: þ
A36: Epilepsia Petit Mal | D36: þ
A37: Insomnio | E37: þ
A38: Lesión nervios | E38: þ
A39: Migrañas | C39: þ
A40: Neurosis | D40: þ
A41: Parálisis | E41: þ
A42: Psicosis | D42: þ
...
