Workbook

Sheet Cotizador
A1: !
I2: =IF(LEN(I3)=5,VLOOKUP(LEFT(I3,2),AuxCP!C:E,3,0),VLOOKUP("0"&LEFT(I3,1),AuxCP!C:E,3,0)) -> Valencia | K2: Zona | N2: COPAGO | O2: COPAGO | P2: COPAGO | Q2: COPAGO | U2: COPAGO | V2: COPAGO
G3: CP | I3: 46019 | K3: =IF(LEN(I3)=5,VLOOKUP(LEFT(I3,2),AuxCP!C:D,2,0),VLOOKUP("0"&LEFT(I3,1),AuxCP!C:D,2,0)) -> 2 | M3: COTIZACIÓN | AE3: PROMOCIONES ACTUALES | AF3: Asegurados | AG3: Promo
B4: Fecha nacimiento | G4: Edad | K4: DESCUENTOS | N4: Go | O4: Plena Vital | P4: Plena Total Vital | Q4: Adeslas Plena | R4: Adeslas Plena Plus | S4: Adeslas Plena Total | T4: Adeslas Plena Extra 150 | U4: Adeslas Seniors | V4: Adeslas Plena Total Seniors | W4: Adeslas NIF | X4: Adeslas Pymes TOTAL | Y4: Adeslas Extra NIF | Z4: Adeslas CIF | AA4: Adeslas Extra CIF | AB4: Adeslas Empresas | AC4: Adeslas Extra Empresas | AE4: Plurianuales | AF4: 1 | AG4: 2 meses gratis
B5: Día | C5: Mes | D5: Año | I5: Edad | AE5: Plurianuales | AF5: >=2 | AG5: 3 meses gratis (2 el primer año)
A6: 1 | G6: 33 | I6: =IF(G6=0,TRUNC((TODAY()-DATE(D6,C6,B6))/365.25,0),G6) -> 33 | K6: =IF(K10="Sí",0.06+K8,K8) -> 0 | M6: SIN DENTAL | N6: =IF((SUM(N57:N71))=0,"",SUM(N57:N71)) -> 108.9 | O6: =IF((SUM(O21:O35))=0,"",SUM(O21:O35)) -> 323.1 | Q6: =IF((SUM(Q21:Q35))=0,"",SUM(Q21:Q35)) -> 358.2 | R6: =IF((SUM(R21:R35))=0,"",SUM(R21:R35)) -> 504 | T6: =IF((SUM(T21:T35))=0,"",SUM(T21:T35)) -> 630.9 | U6: =IF(SUM(U21:U35)=0,"",IF(COUNT($I$6:$I$20)>=4,SUM(U21:U35)*0.9, SUM(U21:U35))) | W6: =IF((SUM(W21:W35))=0,"",SUM(W21:W35)) -> 492 | Y6: =IF(COUNT($I$6:$I$13)>4,SUM(Y21:Y28)*0.9, SUM(Y21:Y28)) -> 0 | Z6: =IF(COUNT($I$6:$I$13)>4,SUM(Z21:Z28)*0.9, SUM(Z21:Z28)) -> 290 | AA6: =IF(COUNT($I$6:$I$13)>4,SUM(AA21:AA28)*0.9, SUM(AA21:AA28)) -> 405 | AB6: =IF(COUNT($I$6:$I$13)>4,SUM(AB21:AB28)*0.9, SUM(AB21:AB28)) -> 267.5 | AC6: =IF(COUNT($I$6:$I$13)>4,SUM(AC21:AC28)*0.9, SUM(AC21:AC28)) -> 359.5 | AE6: Anuales Sin dental | AF6: 1 | AG6: 1 mes gratis
A7: 2 | G7: 43 | I7: =IF(G7=0,TRUNC((TODAY()-DATE(D7,C7,B7))/365.25,0),G7) -> 43 | K7: Descuento contra comisión | M7: CON DENTAL | N7: =IF((SUM(N75:N89))=0,"",SUM(N75:N89)) -> 126.75 | O7: =IF((SUM(O39:O53))=0,"",SUM(O39:O53)) -> 340.95 | P7: =IF((SUM(P39:P53))=0,"",SUM(P39:P53)) -> 391.5 | Q7: =IF((SUM(Q39:Q53))=0,"",SUM(Q39:Q53)) -> 376.05 | R7: =IF((SUM(R39:R53))=0,"",SUM(R39:R53)) -> 521.85 | S7: =IF((SUM(S39:S53))=0,"",SUM(S39:S53)) -> 599.4 | T7: =IF((SUM(T39:T53))=0,"",SUM(T39:T53)) -> 718.85 | U7: =IF((SUM(U39:U53))=0,"",SUM(U39:U53)) | V7: =IF((SUM(V39:V53))=0,"",SUM(V39:V53)) | ... X7: =IF((SUM(X39:X53))=0,"",SUM(X39:X53)) -> 348 | Y7: =IF(OR(Y$6="",Y$6=0),"",Y6+VLOOKUP(COUNT($I$6:$I$13),Precios!$F:$H,3,0)) | AE7: Anuales Sin dental | AF7: >=2 | AG7: 2 meses gratis (1 el primer año)
A8: 3 | G8: 55 | I8: =IF(G8=0,TRUNC((TODAY()-DATE(D8,C8,B8))/365.25,0),G8) -> 55 | K8: 0 | M8: PRECIO SIN DESCUENTO | P8: =IF(SUM(P75:P89)=0,"",SUM(P75:P89)) -> 391.5 | S8: =IF(SUM(S75:S89)=0,"",SUM(S75:S89)) -> 599.4 | V8: =IF(SUM(V75:V89)=0,"",SUM(V75:V89)) | X8: =IF(SUM(X75:X89)=0,"",SUM(X75:X89)) -> 348 | AE8: Anuales Con dental | AF8: 1 | AG8: 2 meses gratis
A9: 4 | G9: 66 | I9: =IF(G9=0,TRUNC((TODAY()-DATE(D9,C9,B9))/365.25,0),G9) -> 66 | K9: ¿Es Anual? | M9: PRIMA ANUAL
A10: 5 | I10: =IF(G10=0,TRUNC((TODAY()-DATE(D10,C10,B10))/365.25,0),G10) -> #NUM! | K10: No | M10: SIN DENTAL | N10: =IF((SUM(N57:N71)*12)=0,"",SUM(N57:N71)*12) -> 1306.8 | O10: =IF((SUM(O21:O35)*12)=0,"",SUM(O21:O35)*12) -> 3877.2 | Q10: =IF((SUM(Q21:Q35)*12)=0,"",SUM(Q21:Q35)*12) -> 4298.4 | R10: =IF((SUM(R21:R35)*12)=0,"",SUM(R21:R35)*12) -> 6048 | T10: =IF((SUM(T21:T35)*12)=0,"",SUM(T21:T35)*12) -> 7570.8 | U10: =IF(IFERROR(IF(AND($K$8>1%,$K$10="Sí"),U$57*(1-($K$6-$K$8))*(1-$K$8)*12,IF(AND($K$6>0%,$K$6<11%),U$57*(1-$K$6)*12,IF($K$6=0,U$57*12))),"")=0,"",IFERROR(IF(AND($K$8>1%,$K$10="Sí"),U$57*(1-($K$6-$K$8))*(1-$K$8)*12,IF(AND($K$6>0%,$K$6<11%),U$57*(1-$K$6)*12,IF($K$6=0,U$57*12))),"")) | W10: =IF((SUM(W21:W35)*12)=0,"",SUM(W21:W35)*12) -> 5904 | Y10: =IFERROR(IF(IF(AND($K$8>1%,$K$10="Sí"),Y$57*(1-($K$6-$K$8))*(1-$K$8)*12,IF(AND($K$6>0%,$K$6<11%),Y$57*(1-$K$6)*12,IF($K$6=0,Y$57*12)))=0,"",IF(AND($K$8>1%,$K$10="Sí"),Y$57*(1-($K$6-$K$8))*(1-$K$8)*12,IF(AND($K$6>0%,$K$6<11%),Y$57*(1-$K$6)*12,IF($K$6=0,Y$57*12)))),"") | Z10: =IFERROR(IF(AND($K$8>1%,$K$10="Sí"),Z$57*(1-($K$6-$K$8))*(1-$K$8)*12,IF(AND($K$6>0%,$K$6<11%),Z$57*(1-$K$6)*12,IF($K$6=0,Z$57*12))),"") -> 624 | AA10: =IFERROR(IF(AND($K$8>1%,$K$10="Sí"),AA$57*(1-($K$6-$K$8))*(1-$K$8)*12,IF(AND($K$6>0%,$K$6<11%),AA$57*(1-$K$6)*12,IF($K$6=0,AA$57*12))),"") -> 918 | AB10: =IFERROR(IF(AND($K$8>1%,$K$10="Sí"),AB$57*(1-($K$6-$K$8))*(1-$K$8)*12,IF(AND($K$6>0%,$K$6<11%),AB$57*(1-$K$6)*12,IF($K$6=0,AB$57*12))),"") -> 702 | AC10: =IFERROR(IF(AND($K$8>1%,$K$10="Sí"),AC$57*(1-($K$6-$K$8))*(1-$K$8)*12,IF(AND($K$6>0%,$K$6<11%),AC$57*(1-$K$6)*12,IF($K$6=0,AC$57*12))),"") -> 978
A11: 6 | I11: =IF(G11=0,TRUNC((TODAY()-DATE(D11,C11,B11))/365.25,0),G11) -> #NUM! | K11: =$K$6 -> 0 | M11: SIN DESCUENTO | N11: =IF((SUM(N57:N71)*12)=0,"",SUM(N57:N71)*12) -> 1306.8 | O11: =IF((SUM(O57:O71)*12)=0,"",SUM(O57:O71)*12) -> 3877.2 | Q11: =IF((SUM(Q57:Q71)*12)=0,"",SUM(Q57:Q71)*12) -> 4298.4 | R11: =IF((SUM(R57:R71)*12)=0,"",SUM(R57:R71)*12) -> 6048 | T11: =IF((SUM(T57:T71)*12)=0,"",SUM(T57:T71)*12) -> 7570.8 | U11: =IFERROR(__xludf.DUMMYFUNCTION("IFERROR(IF($U$10="""","""",IF($K$10=""Sí"",IF($I6="""","""",IF(VLOOKUP(LEFT(U$37,SEARCH(""☃"",SUBSTITUTE(U$37,"" "",""☃"",LEN(U$37)-LEN(SUBSTITUTE(U$37,"" "",""""))))-1),Excepciones!$A:$B,2,0)>=0,IFERROR(INDEX(filter(Precios!$D:$D,(Precios!$A:$A<=$I6)*(Pr"&"ecios!$B:$B>=$I6)*(Precios!$C:$C=U$37))*12,1),""""),""""))*0.94,IF($I6="""","""",IF(VLOOKUP(LEFT(U$37,SEARCH(""☃"",SUBSTITUTE(U$37,"" "",""☃"",LEN(U$37)-LEN(SUBSTITUTE(U$37,"" "",""""))))-1),Excepciones!$A:$B,2,0)>=0,IFERROR(INDEX(filter(Precios!$D:$D,(Pr"&"ecios!$A:$A<=$I6)*(Precios!$B:$B>=$I6)*(Precios!$C:$C=U$37))*12,1),""""),"""")))),"""")"),"") | W11: =IF((SUM(W57:W71)*12)=0,"",SUM(W57:W71)*12) -> 5904 | Y11: =IF(OR(Y8="",Y8=0),"",Y8*12) | Z11: =IFERROR(__xludf.DUMMYFUNCTION("IFERROR(IF($K$10=""Sí"",IF($I6="""","""",IF(VLOOKUP(LEFT(Z$37,SEARCH(""☃"",SUBSTITUTE(Z$37,"" "",""☃"",LEN(Z$37)-LEN(SUBSTITUTE(Z$37,"" "",""""))))-1),Excepciones!$A:$B,2,0)>=0,IFERROR(INDEX(filter(Precios!$D:$D,(Precios!$A:$A<=$I6)*(Precios!$B:$B>=$I6)*("&"Precios!$C:$C=Z$37))*12,1),""""),""""))*0.94,IF($I6="""","""",IF(VLOOKUP(LEFT(Z$37,SEARCH(""☃"",SUBSTITUTE(Z$37,"" "",""☃"",LEN(Z$37)-LEN(SUBSTITUTE(Z$37,"" "",""""))))-1),Excepciones!$A:$B,2,0)>=0,IFERROR(INDEX(filter(Precios!$D:$D,(Precios!$A:$A<=$I6)*("&"Precios!$B:$B>=$I6)*(Precios!$C:$C=Z$37))*12,1),""""),""""))),"""")"),624.0) -> 624 | AA11: =IFERROR(__xludf.DUMMYFUNCTION("IFERROR(IF($K$10=""Sí"",IF($I6="""","""",IF(VLOOKUP(LEFT(AA$37,SEARCH(""☃"",SUBSTITUTE(AA$37,"" "",""☃"",LEN(AA$37)-LEN(SUBSTITUTE(AA$37,"" "",""""))))-1),Excepciones!$A:$B,2,0)>=0,IFERROR(INDEX(filter(Precios!$D:$D,(Precios!$A:$A<=$I6)*(Precios!$B:$B>=$I"&"6)*(Precios!$C:$C=AA$37))*12,1),""""),""""))*0.94,IF($I6="""","""",IF(VLOOKUP(LEFT(AA$37,SEARCH(""☃"",SUBSTITUTE(AA$37,"" "",""☃"",LEN(AA$37)-LEN(SUBSTITUTE(AA$37,"" "",""""))))-1),Excepciones!$A:$B,2,0)>=0,IFERROR(INDEX(filter(Precios!$D:$D,(Precios!$A:$"&"A<=$I6)*(Precios!$B:$B>=$I6)*(Precios!$C:$C=AA$37))*12,1),""""),""""))),"""")"),918.0) -> 918 | AB11: =IFERROR(__xludf.DUMMYFUNCTION("IFERROR(IF($K$10=""Sí"",IF($I6="""","""",IF(VLOOKUP(LEFT(AB$37,SEARCH(""☃"",SUBSTITUTE(AB$37,"" "",""☃"",LEN(AB$37)-LEN(SUBSTITUTE(AB$37,"" "",""""))))-1),Excepciones!$A:$B,2,0)>=0,IFERROR(INDEX(filter(Precios!$D:$D,(Precios!$A:$A<=$I6)*(Precios!$B:$B>=$I"&"6)*(Precios!$C:$C=AB$37))*12,1),""""),""""))*0.94,IF($I6="""","""",IF(VLOOKUP(LEFT(AB$37,SEARCH(""☃"",SUBSTITUTE(AB$37,"" "",""☃"",LEN(AB$37)-LEN(SUBSTITUTE(AB$37,"" "",""""))))-1),Excepciones!$A:$B,2,0)>=0,IFERROR(INDEX(filter(Precios!$D:$D,(Precios!$A:$"&"A<=$I6)*(Precios!$B:$B>=$I6)*(Precios!$C:$C=AB$37))*12,1),""""),""""))),"""")"),702.0) -> 702 | AC11: =IFERROR(__xludf.DUMMYFUNCTION("IFERROR(IF($K$10=""Sí"",IF($I6="""","""",IF(VLOOKUP(LEFT(AC$37,SEARCH(""☃"",SUBSTITUTE(AC$37,"" "",""☃"",LEN(AC$37)-LEN(SUBSTITUTE(AC$37,"" "",""""))))-1),Excepciones!$A:$B,2,0)>=0,IFERROR(INDEX(filter(Precios!$D:$D,(Precios!$A:$A<=$I6)*(Precios!$B:$B>=$I"&"6)*(Precios!$C:$C=AC$37))*12,1),""""),""""))*0.94,IF($I6="""","""",IF(VLOOKUP(LEFT(AC$37,SEARCH(""☃"",SUBSTITUTE(AC$37,"" "",""☃"",LEN(AC$37)-LEN(SUBSTITUTE(AC$37,"" "",""""))))-1),Excepciones!$A:$B,2,0)>=0,IFERROR(INDEX(filter(Precios!$D:$D,(Precios!$A:$"&"A<=$I6)*(Precios!$B:$B>=$I6)*(Precios!$C:$C=AC$37))*12,1),""""),""""))),"""")"),978.0) -> 978
A12: 7 | I12: =IF(G12=0,TRUNC((TODAY()-DATE(D12,C12,B12))/365.25,0),G12) -> #NUM! | K12: =$K$6 -> 0 | M12: 🔻 | N12: =IF(N10="","",N13-N11) -> 0 | O12: =IF(O10="","",O13-O11) -> 0 | Q12: =IF(Q10="","",Q13-Q11) -> 0 | R12: =IF(R10="","",R13-R11) -> 0 | T12: =IF(T10="","",T13-T11) -> 0 | U12: =IF(U10="","",U13-U11) | W12: =IF(W10="","",W13-W11) -> 0 | Y12: =IF(Y10="","",Y13-Y11) | Z12: =IF(Z10="","",Z13-Z11) -> 0 | AA12: =IF(AA10="","",AA13-AA11) -> 0 | AB12: =IF(AB10="","",AB13-AB11) -> 0 | AC12: =IF(AC10="","",AC13-AC11) -> 0
A13: 8 | I13: =IF(G13=0,TRUNC((TODAY()-DATE(D13,C13,B13))/365.25,0),G13) -> #NUM! | K13: =$K$6 -> 0 | M13: VALOR DE VENTA | N13: =N11 -> 1306.8 | O13: =IF($K$10="Sí",IF($K$6=0.11,O10*0.82,IF($K$6=0.1,O10*0.84,IF($K$6=0.09,O10*0.86,IF($K$6=0.08,O10*0.88,IF($K$6=0.07,O10*0.89,O10))))),IF($K$6=0.05,O10*0.82,IF($K$6=0.04,O10*0.84,IF($K$6=0.03,O10*0.86,IF($K$6=0.02,O10*0.88,IF($K$6=0.01,O10*0.89,O10)))))) -> 3877.2 | Q13: =IF($K$10="Sí",IF($K$6=0.11,Q10*0.82,IF($K$6=0.1,Q10*0.84,IF($K$6=0.09,Q10*0.86,IF($K$6=0.08,Q10*0.88,IF($K$6=0.07,Q10*0.89,Q10))))),IF($K$6=0.05,Q10*0.82,IF($K$6=0.04,Q10*0.84,IF($K$6=0.03,Q10*0.86,IF($K$6=0.02,Q10*0.88,IF($K$6=0.01,Q10*0.89,Q10)))))) -> 4298.4 | R13: =IF($K$10="Sí",IF($K$6=0.11,R10*0.82,IF($K$6=0.1,R10*0.84,IF($K$6=0.09,R10*0.86,IF($K$6=0.08,R10*0.88,IF($K$6=0.07,R10*0.89,R10))))),IF($K$6=0.05,R10*0.82,IF($K$6=0.04,R10*0.84,IF($K$6=0.03,R10*0.86,IF($K$6=0.02,R10*0.88,IF($K$6=0.01,R10*0.89,R10)))))) -> 6048 | T13: =IF($K$10="Sí",IF($K$6=0.11,T10*0.82,IF($K$6=0.1,T10*0.84,IF($K$6=0.09,T10*0.86,IF($K$6=0.08,T10*0.88,IF($K$6=0.07,T10*0.89,T10))))),IF($K$6=0.05,T10*0.82,IF($K$6=0.04,T10*0.84,IF($K$6=0.03,T10*0.86,IF($K$6=0.02,T10*0.88,IF($K$6=0.01,T10*0.89,T10)))))) -> 7570.8 | U13: =IF($K$10="Sí",IF($K$6=0.11,U10*0.82,IF($K$6=0.1,U10*0.84,IF($K$6=0.09,U10*0.86,IF($K$6=0.08,U10*0.88,IF($K$6=0.07,U10*0.89,U10))))),IF($K$6=0.05,U10*0.82,IF($K$6=0.04,U10*0.84,IF($K$6=0.03,U10*0.86,IF($K$6=0.02,U10*0.88,IF($K$6=0.01,U10*0.89,U10)))))) | W13: =IF($K$10="Sí",IF($K$6=0.11,W10*0.82,IF($K$6=0.1,W10*0.84,IF($K$6=0.09,W10*0.86,IF($K$6=0.08,W10*0.88,IF($K$6=0.07,W10*0.89,W10))))),IF($K$6=0.05,W10*0.82,IF($K$6=0.04,W10*0.84,IF($K$6=0.03,W10*0.86,IF($K$6=0.02,W10*0.88,IF($K$6=0.01,W10*0.89,W10)))))) -> 5904 | Z13: =IF($K$10="Sí",IF($K$6=0.16,Z10*0.82,IF($K$6=0.15,Z10*0.84,IF($K$6=0.14,Z10*0.86,IF($K$6=0.13,Z10*0.88,IF($K$6=0.12,Z10*0.89,IF($K$6=0.11,Z10*0.91,IF($K$6=0.1,Z10*0.93,IF($K$6=0.09,Z10*0.95,IF($K$6=0.08,Z10*0.96,IF($K$6=0.07,Z10*0.98,Z10)))))))))),IF($K$6=0.1,Z10*0.82,IF($K$6=0.09,Z10*0.84,IF($K$6=0.08,Z10*0.86,IF($K$6=0.07,Z10*0.88,IF($K$6=0.06,Z10*0.89,IF($K$6=0.05,Z10*0.91,IF($K$6=0.04,Z10*0.93,IF($K$6=0.03,Z10*0.95,IF($K$6=0.02,Z10*0.96,IF($K$6=0.01,Z10*0.98,Z10))))))))))) -> 624 | AA13: =IF($K$10="Sí",IF($K$6=0.16,AA10*0.82,IF($K$6=0.15,AA10*0.84,IF($K$6=0.14,AA10*0.86,IF($K$6=0.13,AA10*0.88,IF($K$6=0.12,AA10*0.89,IF($K$6=0.11,AA10*0.91,IF($K$6=0.1,AA10*0.93,IF($K$6=0.09,AA10*0.95,IF($K$6=0.08,AA10*0.96,IF($K$6=0.07,AA10*0.98,AA10)))))))))),IF($K$6=0.1,AA10*0.82,IF($K$6=0.09,AA10*0.84,IF($K$6=0.08,AA10*0.86,IF($K$6=0.07,AA10*0.88,IF($K$6=0.06,AA10*0.89,IF($K$6=0.05,AA10*0.91,IF($K$6=0.04,AA10*0.93,IF($K$6=0.03,AA10*0.95,IF($K$6=0.02,AA10*0.96,IF($K$6=0.01,AA10*0.98,AA10))))))))))) -> 918 | AB13: =IF($K$10="Sí",IF($K$6=0.16,AB10*0.82,IF($K$6=0.15,AB10*0.84,IF($K$6=0.14,AB10*0.86,IF($K$6=0.13,AB10*0.88,IF($K$6=0.12,AB10*0.89,IF($K$6=0.11,AB10*0.91,IF($K$6=0.1,AB10*0.93,IF($K$6=0.09,AB10*0.95,IF($K$6=0.08,AB10*0.96,IF($K$6=0.07,AB10*0.98,AB10)))))))))),IF($K$6=0.1,AB10*0.82,IF($K$6=0.09,AB10*0.84,IF($K$6=0.08,AB10*0.86,IF($K$6=0.07,AB10*0.88,IF($K$6=0.06,AB10*0.89,IF($K$6=0.05,AB10*0.91,IF($K$6=0.04,AB10*0.93,IF($K$6=0.03,AB10*0.95,IF($K$6=0.02,AB10*0.96,IF($K$6=0.01,AB10*0.98,AB10))))))))))) -> 702 | AC13: =IF($K$10="Sí",IF($K$6=0.16,AC10*0.82,IF($K$6=0.15,AC10*0.84,IF($K$6=0.14,AC10*0.86,IF($K$6=0.13,AC10*0.88,IF($K$6=0.12,AC10*0.89,IF($K$6=0.11,AC10*0.91,IF($K$6=0.1,AC10*0.93,IF($K$6=0.09,AC10*0.95,IF($K$6=0.08,AC10*0.96,IF($K$6=0.07,AC10*0.98,AC10)))))))))),IF($K$6=0.1,AC10*0.82,IF($K$6=0.09,AC10*0.84,IF($K$6=0.08,AC10*0.86,IF($K$6=0.07,AC10*0.88,IF($K$6=0.06,AC10*0.89,IF($K$6=0.05,AC10*0.91,IF($K$6=0.04,AC10*0.93,IF($K$6=0.03,AC10*0.95,IF($K$6=0.02,AC10*0.96,IF($K$6=0.01,AC10*0.98,AC10))))))))))) -> 978
A14: 9 | I14: =IF(G14=0,TRUNC((TODAY()-DATE(D14,C14,B14))/365.25,0),G14) -> #NUM! | M14: CON DENTAL | N14: =IF((SUM(N75:N89)*12)=0,"",SUM(N75:N89)*12) -> 1521 | O14: =IF((SUM(O39:O53)*12)=0,"",SUM(O39:O53)*12) -> 4091.4 | P14: =IF((SUM(P39:P53)*12)=0,"",SUM(P39:P53)*12) -> 4698 | Q14: =IF((SUM(Q39:Q53)*12)=0,"",SUM(Q39:Q53)*12) -> 4512.6 | R14: =IF((SUM(R39:R53)*12)=0,"",SUM(R39:R53)*12) -> 6262.2 | S14: =IF((SUM(S39:S53)*12)=0,"",SUM(S39:S53)*12) -> 7192.8 | T14: =IF((SUM(T39:T53)*12)=0,"",SUM(T39:T53)*12) -> 8626.2 | U14: =IF((SUM(U39:U53)*12)=0,"",SUM(U39:U53)*12) | V14: =IF((SUM(V39:V53)*12)=0,"",SUM(V39:V53)*12) | W14: =IF((SUM(W39:W53)*12)=0,"",SUM(W39:W53)*12) -> 6118.2 | X14: =IF((SUM(X39:X53)*12*0.9)=0,"",SUM(X39:X53)*12*0.9) -> 3758.4 | Y14: =IF(OR(Y7="",Y7=0),"",Y7*12) | Z14: =IF(OR(Z7="",Z7=0),"",Z7*12) | AA14: =IF(OR(AA7="",AA7=0),"",AA7*12) | AB14: =IF(OR(AB7="",AB7=0),"",AB7*12) | AC14: =IF(OR(AC7="",AC7=0),"",AC7*12)
A15: 10 | I15: =IF(G15=0,TRUNC((TODAY()-DATE(D15,C15,B15))/365.25,0),G15) -> #NUM! | M15: SIN DESCUENTO | N15: =IF((SUM(N75:N89)*12)=0,"",SUM(N75:N89)*12) -> 1521 | O15: =IF((SUM(O75:O89)*12)=0,"",SUM(O75:O89)*12) -> 4091.4 | P15: =IF((SUM(P75:P89)*12)=0,"",SUM(P75:P89)*12) -> 4698 | Q15: =IF((SUM(Q75:Q89)*12)=0,"",SUM(Q75:Q89)*12) -> 4512.6 | R15: =IF((SUM(R75:R89)*12)=0,"",SUM(R75:R89)*12) -> 6262.2 | S15: =IF((SUM(S75:S89)*12)=0,"",SUM(S75:S89)*12) -> 7192.8 | T15: =IF((SUM(T75:T89)*12)=0,"",SUM(T75:T89)*12) -> 8626.2 | U15: =IF((SUM(U75:U89)*12)=0,"",SUM(U75:U89)*12) | ... X15: =IF((SUM(X75:X89)*12)=0,"",SUM(X75:X89)*12) -> 4176
A16: 11 | I16: =IF(G16=0,TRUNC((TODAY()-DATE(D16,C16,B16))/365.25,0),G16) -> #NUM! | M16: 🔻 | N16: =IF(N14="","",N17-N15) -> 0 | O16: =IF(O14="","",O17-O15) -> 0 | P16: =IF(P14="","",P17-P15) -> 0 | Q16: =IF(Q14="","",Q17-Q15) -> 0 | R16: =IF(R14="","",R17-R15) -> 0 | S16: =IF(S14="","",S17-S15) -> 0 | T16: =IF(T14="","",T17-T15) -> 0 | U16: =IF(U14="","",U17-U15) | ... X16: =IF(X14="","",X17-X15) -> -417.6
A17: 12 | I17: =IF(G17=0,TRUNC((TODAY()-DATE(D17,C17,B17))/365.25,0),G17) -> #NUM! | M17: VALOR DE VENTA | N17: =N14 -> 1521 | O17: =IF($K$10="Sí",IF($K$6=0.11,O14*0.82,IF($K$6=0.1,O14*0.84,IF($K$6=0.09,O14*0.86,IF($K$6=0.08,O14*0.88,IF($K$6=0.07,O14*0.89,O14))))),IF($K$6=0.05,O14*0.82,IF($K$6=0.04,O14*0.84,IF($K$6=0.03,O14*0.86,IF($K$6=0.02,O14*0.88,IF($K$6=0.01,O14*0.89,O14)))))) -> 4091.4 | P17: =P14 -> 4698 | Q17: =IF($K$10="Sí",IF($K$6=0.11,Q14*0.82,IF($K$6=0.1,Q14*0.84,IF($K$6=0.09,Q14*0.86,IF($K$6=0.08,Q14*0.88,IF($K$6=0.07,Q14*0.89,Q14))))),IF($K$6=0.05,Q14*0.82,IF($K$6=0.04,Q14*0.84,IF($K$6=0.03,Q14*0.86,IF($K$6=0.02,Q14*0.88,IF($K$6=0.01,Q14*0.89,Q14)))))) -> 4512.6 | R17: =IF($K$10="Sí",IF($K$6=0.11,R14*0.82,IF($K$6=0.1,R14*0.84,IF($K$6=0.09,R14*0.86,IF($K$6=0.08,R14*0.88,IF($K$6=0.07,R14*0.89,R14))))),IF($K$6=0.05,R14*0.82,IF($K$6=0.04,R14*0.84,IF($K$6=0.03,R14*0.86,IF($K$6=0.02,R14*0.88,IF($K$6=0.01,R14*0.89,R14)))))) -> 6262.2 | S17: =S14 -> 7192.8 | T17: =IF($K$10="Sí",IF($K$6=0.11,T14*0.82,IF($K$6=0.1,T14*0.84,IF($K$6=0.09,T14*0.86,IF($K$6=0.08,T14*0.88,IF($K$6=0.07,T14*0.89,T14))))),IF($K$6=0.05,T14*0.82,IF($K$6=0.04,T14*0.84,IF($K$6=0.03,T14*0.86,IF($K$6=0.02,T14*0.88,IF($K$6=0.01,T14*0.89,T14)))))) -> 8626.2 | U17: =IF($K$10="Sí",IF($K$6=0.11,U14*0.82,IF($K$6=0.1,U14*0.84,IF($K$6=0.09,U14*0.86,IF($K$6=0.08,U14*0.88,IF($K$6=0.07,U14*0.89,U14))))),IF($K$6=0.05,U14*0.82,IF($K$6=0.04,U14*0.84,IF($K$6=0.03,U14*0.86,IF($K$6=0.02,U14*0.88,IF($K$6=0.01,U14*0.89,U14)))))) | V17: =V14 | W17: =IF($K$10="Sí",IF($K$6=0.11,W14*0.82,IF($K$6=0.1,W14*0.84,IF($K$6=0.09,W14*0.86,IF($K$6=0.08,W14*0.88,IF($K$6=0.07,W14*0.89,W14))))),IF($K$6=0.05,W14*0.82,IF($K$6=0.04,W14*0.84,IF($K$6=0.03,W14*0.86,IF($K$6=0.02,W14*0.88,IF($K$6=0.01,W14*0.89,W14)))))) -> 6118.2 | X17: =X14 -> 3758.4
A18: 13 | I18: =IF(G18=0,TRUNC((TODAY()-DATE(D18,C18,B18))/365.25,0),G18) -> #NUM!
A19: 14 | I19: =IF(G19=0,TRUNC((TODAY()-DATE(D19,C19,B19))/365.25,0),G19) -> #NUM! | L19: SIN DENTAL | N19: ="Go"&" "&$K$3 -> Go 2 | O19: ="Plena Vital"&" "&$K$3 -> Plena Vital 2 | P19: ="Plena Total vital"&" "&$K$3 -> Plena Total vital 2 | Q19: ="Plena"&" "&$K$3 -> Plena 2 | R19: ="Plena Plus"&" "&$K$3 -> Plena Plus 2 | S19: ="Plena Total"&" "&$K$3 -> Plena Total 2 | T19: ="Plena Extra 150"&" "&$K$3 -> Plena Extra 150 2 | U19: ="Seniors"&" "&$K$3 -> Seniors 2 | V19: ="Seniors total"&" "&$K$3 -> Seniors total 2 | W19: ="Negocios NIF"&" "&$K$3 -> Negocios NIF 2 | X19: ="Pymes TOTAL"&" "&$K$3 -> Pymes TOTAL 2 | Y19: =IF(OR(COUNT(#REF!)=1,COUNT(#REF!)=2),"Extra Negocios NIF"&" "&$K$3&" "&COUNT(#REF!),"Extra Negocios NIF"&" "&$K$3) -> Extra Negocios NIF 2 | Z19: ="Negocios CIF"&" "&$K$3 -> Negocios CIF 2 | AA19: ="Extra Negocios CIF"&" "&$K$3 -> Extra Negocios CIF 2 | AB19: ="Empresas"&" "&$K$3 -> Empresas 2 | AC19: ="Extra Empresas"&" "&$K$3 -> Extra Empresas 2
A20: 15 | I20: =IF(G20=0,TRUNC((TODAY()-DATE(D20,C20,B20))/365.25,0),G20) -> #NUM!
L21: 1 | N21: =N57 -> 19.35 | O21: =IF(OR(O57="",O57=0),"",O57*(1-$K$8)) -> 45.45 | Q21: =IF(OR(Q57="",Q57=0),"",Q57*(1-$K$8)) -> 55.8 | R21: =IF(OR(R57="",R57=0),"",R57*(1-$K$8)) -> 67.5 | T21: =IF(OR(T57="",T57=0),"",T57*(1-$K$8)) -> 99 | U21: =IF(OR(U57="",U57=0),"",U57*(1-$K$8)) | W21: =IFERROR(__xludf.DUMMYFUNCTION("IFERROR(IF($I6="""","""",IF(VLOOKUP(LEFT(W$37,SEARCH(""☃"",SUBSTITUTE(W$37,"" "",""☃"",LEN(W$37)-LEN(SUBSTITUTE(W$37,"" "",""""))))-1),Excepciones!$A:$B,2,0)>=0,IFERROR(INDEX(filter(Precios!$D:$D,(Precios!$A:$A<=$I6)*(Precios!$B:$B>=$I6)*(Precios!$C:$C=W$"&"37)),1)*(1-$K$6),""No asegurable""),""No asegurable"")),"""")"),63.5) -> 63.5 | Y21: =IFERROR(__xludf.DUMMYFUNCTION("IFERROR(IF($I6="""","""",IF(VLOOKUP(LEFT(Y$37,SEARCH(""☃"",SUBSTITUTE(Y$37,"" "",""☃"",LEN(Y$37)-LEN(SUBSTITUTE(Y$37,"" "",""""))))-1),Excepciones!$A:$B,2,0)>=0,IFERROR((INDEX(filter(Precios!$D:$D,(Precios!$A:$A<=$I6)*(Precios!$B:$B>=$I6)*(Precios!$C:$C=Y"&"$37)),1)*(1-$K$6)+VLOOKUP($L21,Precios!$F:$G,2,0)),""No asegurable""),""No asegurable"")),"""")"),"") | Z21: =IFERROR(__xludf.DUMMYFUNCTION("IFERROR(IF($I6="""","""",IF(VLOOKUP(LEFT(Z$37,SEARCH(""☃"",SUBSTITUTE(Z$37,"" "",""☃"",LEN(Z$37)-LEN(SUBSTITUTE(Z$37,"" "",""""))))-1),Excepciones!$A:$B,2,0)>=0,IFERROR(INDEX(filter(Precios!$D:$D,(Precios!$A:$A<=$I6)*(Precios!$B:$B>=$I6)*(Precios!$C:$C=Z$"&"37)),1)*(1-$K$6),""No asegurable""),""No asegurable"")),"""")"),52.0) -> 52 | AA21: =IFERROR(__xludf.DUMMYFUNCTION("IFERROR(IF($I6="""","""",IF(VLOOKUP(LEFT(AA$37,SEARCH(""☃"",SUBSTITUTE(AA$37,"" "",""☃"",LEN(AA$37)-LEN(SUBSTITUTE(AA$37,"" "",""""))))-1),Excepciones!$A:$B,2,0)>=0,IFERROR(INDEX(filter(Precios!$D:$D,(Precios!$A:$A<=$I6)*(Precios!$B:$B>=$I6)*(Precios!$C:$"&"C=AA$37)),1)*(1-$K$6),""No asegurable""),""No asegurable"")),"""")"),76.5) -> 76.5 | AB21: =IFERROR(__xludf.DUMMYFUNCTION("IFERROR(IF($I6="""","""",IF(VLOOKUP(LEFT(AB$37,SEARCH(""☃"",SUBSTITUTE(AB$37,"" "",""☃"",LEN(AB$37)-LEN(SUBSTITUTE(AB$37,"" "",""""))))-1),Excepciones!$A:$B,2,0)>=0,IFERROR(INDEX(filter(Precios!$D:$D,(Precios!$A:$A<=$I6)*(Precios!$B:$B>=$I6)*(Precios!$C:$"&"C=AB$37)),1)*(1-$K$6),""No asegurable""),""No asegurable"")),"""")"),58.5) -> 58.5 | AC21: =IFERROR(__xludf.DUMMYFUNCTION("IFERROR(IF($I6="""","""",IF(VLOOKUP(LEFT(AC$37,SEARCH(""☃"",SUBSTITUTE(AC$37,"" "",""☃"",LEN(AC$37)-LEN(SUBSTITUTE(AC$37,"" "",""""))))-1),Excepciones!$A:$B,2,0)>=0,IFERROR(INDEX(filter(Precios!$D:$D,(Precios!$A:$A<=$I6)*(Precios!$B:$B>=$I6)*(Precios!$C:$"&"C=AC$37)),1)*(1-$K$6),""No asegurable""),""No asegurable"")),"""")"),81.5) -> 81.5
L22: 2 | N22: =N58 -> 19.35 | O22: =IF(OR(O58="",O58=0),"",O58*(1-$K$8)) -> 45.45 | Q22: =IF(OR(Q58="",Q58=0),"",Q58*(1-$K$8)) -> 55.8 | R22: =IF(OR(R58="",R58=0),"",R58*(1-$K$8)) -> 67.5 | T22: =IF(OR(T58="",T58=0),"",T58*(1-$K$8)) -> 99 | U22: =IF(OR(U58="",U58=0),"",U58*(1-$K$8)) | W22: =IFERROR(__xludf.DUMMYFUNCTION("IFERROR(IF($I7="""","""",IF(VLOOKUP(LEFT(W$37,SEARCH(""☃"",SUBSTITUTE(W$37,"" "",""☃"",LEN(W$37)-LEN(SUBSTITUTE(W$37,"" "",""""))))-1),Excepciones!$A:$B,2,0)>=0,IFERROR(INDEX(filter(Precios!$D:$D,(Precios!$A:$A<=$I7)*(Precios!$B:$B>=$I7)*(Precios!$C:$C=W$"&"37)),1)*(1-$K$6),""No asegurable""),""No asegurable"")),"""")"),63.5) -> 63.5 | Y22: =IFERROR(__xludf.DUMMYFUNCTION("IFERROR(IF($I7="""","""",IF(VLOOKUP(LEFT(Y$37,SEARCH(""☃"",SUBSTITUTE(Y$37,"" "",""☃"",LEN(Y$37)-LEN(SUBSTITUTE(Y$37,"" "",""""))))-1),Excepciones!$A:$B,2,0)>=0,IFERROR((INDEX(filter(Precios!$D:$D,(Precios!$A:$A<=$I7)*(Precios!$B:$B>=$I7)*(Precios!$C:$C=Y"&"$37)),1)*(1-$K$6)+VLOOKUP($L22,Precios!$F:$G,2,0)),""No asegurable""),""No asegurable"")),"""")"),"") | Z22: =IFERROR(__xludf.DUMMYFUNCTION("IFERROR(IF($I7="""","""",IF(VLOOKUP(LEFT(Z$37,SEARCH(""☃"",SUBSTITUTE(Z$37,"" "",""☃"",LEN(Z$37)-LEN(SUBSTITUTE(Z$37,"" "",""""))))-1),Excepciones!$A:$B,2,0)>=0,IFERROR(INDEX(filter(Precios!$D:$D,(Precios!$A:$A<=$I7)*(Precios!$B:$B>=$I7)*(Precios!$C:$C=Z$"&"37)),1)*(1-$K$6),""No asegurable""),""No asegurable"")),"""")"),52.0) -> 52 | AA22: =IFERROR(__xludf.DUMMYFUNCTION("IFERROR(IF($I7="""","""",IF(VLOOKUP(LEFT(AA$37,SEARCH(""☃"",SUBSTITUTE(AA$37,"" "",""☃"",LEN(AA$37)-LEN(SUBSTITUTE(AA$37,"" "",""""))))-1),Excepciones!$A:$B,2,0)>=0,IFERROR(INDEX(filter(Precios!$D:$D,(Precios!$A:$A<=$I7)*(Precios!$B:$B>=$I7)*(Precios!$C:$"&"C=AA$37)),1)*(1-$K$6),""No asegurable""),""No asegurable"")),"""")"),76.5) -> 76.5 | AB22: =IFERROR(__xludf.DUMMYFUNCTION("IFERROR(IF($I7="""","""",IF(VLOOKUP(LEFT(AB$37,SEARCH(""☃"",SUBSTITUTE(AB$37,"" "",""☃"",LEN(AB$37)-LEN(SUBSTITUTE(AB$37,"" "",""""))))-1),Excepciones!$A:$B,2,0)>=0,IFERROR(INDEX(filter(Precios!$D:$D,(Precios!$A:$A<=$I7)*(Precios!$B:$B>=$I7)*(Precios!$C:$"&"C=AB$37)),1)*(1-$K$6),""No asegurable""),""No asegurable"")),"""")"),58.5) -> 58.5 | AC22: =IFERROR(__xludf.DUMMYFUNCTION("IFERROR(IF($I7="""","""",IF(VLOOKUP(LEFT(AC$37,SEARCH(""☃"",SUBSTITUTE(AC$37,"" "",""☃"",LEN(AC$37)-LEN(SUBSTITUTE(AC$37,"" "",""""))))-1),Excepciones!$A:$B,2,0)>=0,IFERROR(INDEX(filter(Precios!$D:$D,(Precios!$A:$A<=$I7)*(Precios!$B:$B>=$I7)*(Precios!$C:$"&"C=AC$37)),1)*(1-$K$6),""No asegurable""),""No asegurable"")),"""")"),81.5) -> 81.5
L23: 3 | N23: =N59 -> 35.1 | O23: =IF(OR(O59="",O59=0),"",O59*(1-$K$8)) -> 85.5 | Q23: =IF(OR(Q59="",Q59=0),"",Q59*(1-$K$8)) -> 96.3 | R23: =IF(OR(R59="",R59=0),"",R59*(1-$K$8)) -> 139.5 | T23: =IF(OR(T59="",T59=0),"",T59*(1-$K$8)) -> 162 | U23: =IF(OR(U59="",U59=0),"",U59*(1-$K$8)) | W23: =IFERROR(__xludf.DUMMYFUNCTION("IFERROR(IF($I8="""","""",IF(VLOOKUP(LEFT(W$37,SEARCH(""☃"",SUBSTITUTE(W$37,"" "",""☃"",LEN(W$37)-LEN(SUBSTITUTE(W$37,"" "",""""))))-1),Excepciones!$A:$B,2,0)>=0,IFERROR(INDEX(filter(Precios!$D:$D,(Precios!$A:$A<=$I8)*(Precios!$B:$B>=$I8)*(Precios!$C:$C=W$"&"37)),1)*(1-$K$6),""No asegurable""),""No asegurable"")),"""")"),127.0) -> 127 | Y23: =IFERROR(__xludf.DUMMYFUNCTION("IFERROR(IF($I8="""","""",IF(VLOOKUP(LEFT(Y$37,SEARCH(""☃"",SUBSTITUTE(Y$37,"" "",""☃"",LEN(Y$37)-LEN(SUBSTITUTE(Y$37,"" "",""""))))-1),Excepciones!$A:$B,2,0)>=0,IFERROR((INDEX(filter(Precios!$D:$D,(Precios!$A:$A<=$I8)*(Precios!$B:$B>=$I8)*(Precios!$C:$C=Y"&"$37)),1)*(1-$K$6)+VLOOKUP($L23,Precios!$F:$G,2,0)),""No asegurable""),""No asegurable"")),"""")"),"") | Z23: =IFERROR(__xludf.DUMMYFUNCTION("IFERROR(IF($I8="""","""",IF(VLOOKUP(LEFT(Z$37,SEARCH(""☃"",SUBSTITUTE(Z$37,"" "",""☃"",LEN(Z$37)-LEN(SUBSTITUTE(Z$37,"" "",""""))))-1),Excepciones!$A:$B,2,0)>=0,IFERROR(INDEX(filter(Precios!$D:$D,(Precios!$A:$A<=$I8)*(Precios!$B:$B>=$I8)*(Precios!$C:$C=Z$"&"37)),1)*(1-$K$6),""No asegurable""),""No asegurable"")),"""")"),81.0) -> 81 | AA23: =IFERROR(__xludf.DUMMYFUNCTION("IFERROR(IF($I8="""","""",IF(VLOOKUP(LEFT(AA$37,SEARCH(""☃"",SUBSTITUTE(AA$37,"" "",""☃"",LEN(AA$37)-LEN(SUBSTITUTE(AA$37,"" "",""""))))-1),Excepciones!$A:$B,2,0)>=0,IFERROR(INDEX(filter(Precios!$D:$D,(Precios!$A:$A<=$I8)*(Precios!$B:$B>=$I8)*(Precios!$C:$"&"C=AA$37)),1)*(1-$K$6),""No asegurable""),""No asegurable"")),"""")"),115.0) -> 115 | AB23: =IFERROR(__xludf.DUMMYFUNCTION("IFERROR(IF($I8="""","""",IF(VLOOKUP(LEFT(AB$37,SEARCH(""☃"",SUBSTITUTE(AB$37,"" "",""☃"",LEN(AB$37)-LEN(SUBSTITUTE(AB$37,"" "",""""))))-1),Excepciones!$A:$B,2,0)>=0,IFERROR(INDEX(filter(Precios!$D:$D,(Precios!$A:$A<=$I8)*(Precios!$B:$B>=$I8)*(Precios!$C:$"&"C=AB$37)),1)*(1-$K$6),""No asegurable""),""No asegurable"")),"""")"),58.5) -> 58.5 | AC23: =IFERROR(__xludf.DUMMYFUNCTION("IFERROR(IF($I8="""","""",IF(VLOOKUP(LEFT(AC$37,SEARCH(""☃"",SUBSTITUTE(AC$37,"" "",""☃"",LEN(AC$37)-LEN(SUBSTITUTE(AC$37,"" "",""""))))-1),Excepciones!$A:$B,2,0)>=0,IFERROR(INDEX(filter(Precios!$D:$D,(Precios!$A:$A<=$I8)*(Precios!$B:$B>=$I8)*(Precios!$C:$"&"C=AC$37)),1)*(1-$K$6),""No asegurable""),""No asegurable"")),"""")"),81.5) -> 81.5
L24: 4 | N24: =N60 -> 35.1 | O24: =IF(OR(O60="",O60=0),"",O60*(1-$K$8)) -> 146.7 | Q24: =IF(OR(Q60="",Q60=0),"",Q60*(1-$K$8)) -> 150.3 | R24: =IF(OR(R60="",R60=0),"",R60*(1-$K$8)) -> 229.5 | T24: =IF(OR(T60="",T60=0),"",T60*(1-$K$8)) -> 270.9 | U24: =IF(OR(U60="",U60=0),"",U60*(1-$K$8)) | W24: =IFERROR(__xludf.DUMMYFUNCTION("IFERROR(IF($I9="""","""",IF(VLOOKUP(LEFT(W$37,SEARCH(""☃"",SUBSTITUTE(W$37,"" "",""☃"",LEN(W$37)-LEN(SUBSTITUTE(W$37,"" "",""""))))-1),Excepciones!$A:$B,2,0)>=0,IFERROR(INDEX(filter(Precios!$D:$D,(Precios!$A:$A<=$I9)*(Precios!$B:$B>=$I9)*(Precios!$C:$C=W$"&"37)),1)*(1-$K$6),""No asegurable""),""No asegurable"")),"""")"),238.0) -> 238 | Y24: =IFERROR(__xludf.DUMMYFUNCTION("IFERROR(IF($I9="""","""",IF(VLOOKUP(LEFT(Y$37,SEARCH(""☃"",SUBSTITUTE(Y$37,"" "",""☃"",LEN(Y$37)-LEN(SUBSTITUTE(Y$37,"" "",""""))))-1),Excepciones!$A:$B,2,0)>=0,IFERROR((INDEX(filter(Precios!$D:$D,(Precios!$A:$A<=$I9)*(Precios!$B:$B>=$I9)*(Precios!$C:$C=Y"&"$37)),1)*(1-$K$6)+VLOOKUP($L24,Precios!$F:$G,2,0)),""No asegurable""),""No asegurable"")),"""")"),"") | Z24: =IFERROR(__xludf.DUMMYFUNCTION("IFERROR(IF($I9="""","""",IF(VLOOKUP(LEFT(Z$37,SEARCH(""☃"",SUBSTITUTE(Z$37,"" "",""☃"",LEN(Z$37)-LEN(SUBSTITUTE(Z$37,"" "",""""))))-1),Excepciones!$A:$B,2,0)>=0,IFERROR(INDEX(filter(Precios!$D:$D,(Precios!$A:$A<=$I9)*(Precios!$B:$B>=$I9)*(Precios!$C:$C=Z$"&"37)),1)*(1-$K$6),""No asegurable""),""No asegurable"")),"""")"),105.0) -> 105 | AA24: =IFERROR(__xludf.DUMMYFUNCTION("IFERROR(IF($I9="""","""",IF(VLOOKUP(LEFT(AA$37,SEARCH(""☃"",SUBSTITUTE(AA$37,"" "",""☃"",LEN(AA$37)-LEN(SUBSTITUTE(AA$37,"" "",""""))))-1),Excepciones!$A:$B,2,0)>=0,IFERROR(INDEX(filter(Precios!$D:$D,(Precios!$A:$A<=$I9)*(Precios!$B:$B>=$I9)*(Precios!$C:$"&"C=AA$37)),1)*(1-$K$6),""No asegurable""),""No asegurable"")),"""")"),137.0) -> 137 | AB24: =IFERROR(__xludf.DUMMYFUNCTION("IFERROR(IF($I9="""","""",IF(VLOOKUP(LEFT(AB$37,SEARCH(""☃"",SUBSTITUTE(AB$37,"" "",""☃"",LEN(AB$37)-LEN(SUBSTITUTE(AB$37,"" "",""""))))-1),Excepciones!$A:$B,2,0)>=0,IFERROR(INDEX(filter(Precios!$D:$D,(Precios!$A:$A<=$I9)*(Precios!$B:$B>=$I9)*(Precios!$C:$"&"C=AB$37)),1)*(1-$K$6),""No asegurable""),""No asegurable"")),"""")"),92.0) -> 92 | AC24: =IFERROR(__xludf.DUMMYFUNCTION("IFERROR(IF($I9="""","""",IF(VLOOKUP(LEFT(AC$37,SEARCH(""☃"",SUBSTITUTE(AC$37,"" "",""☃"",LEN(AC$37)-LEN(SUBSTITUTE(AC$37,"" "",""""))))-1),Excepciones!$A:$B,2,0)>=0,IFERROR(INDEX(filter(Precios!$D:$D,(Precios!$A:$A<=$I9)*(Precios!$B:$B>=$I9)*(Precios!$C:$"&"C=AC$37)),1)*(1-$K$6),""No asegurable""),""No asegurable"")),"""")"),115.0) -> 115
L25: 5 | N25: =N61 | O25: =IF(OR(O61="",O61=0),"",O61*(1-$K$8)) | Q25: =IF(OR(Q61="",Q61=0),"",Q61*(1-$K$8)) | R25: =IF(OR(R61="",R61=0),"",R61*(1-$K$8)) | T25: =IF(OR(T61="",T61=0),"",T61*(1-$K$8)) | U25: =IF(OR(U61="",U61=0),"",U61*(1-$K$8)) | W25: =IFERROR(__xludf.DUMMYFUNCTION("IFERROR(IF($I10="""","""",IF(VLOOKUP(LEFT(W$37,SEARCH(""☃"",SUBSTITUTE(W$37,"" "",""☃"",LEN(W$37)-LEN(SUBSTITUTE(W$37,"" "",""""))))-1),Excepciones!$A:$B,2,0)>=0,IFERROR(INDEX(filter(Precios!$D:$D,(Precios!$A:$A<=$I10)*(Precios!$B:$B>=$I10)*(Precios!$C:$C"&"=W$37)),1)*(1-$K$6),""No asegurable""),""No asegurable"")),"""")"),"") | Y25: =IFERROR(__xludf.DUMMYFUNCTION("IFERROR(IF($I10="""","""",IF(VLOOKUP(LEFT(Y$37,SEARCH(""☃"",SUBSTITUTE(Y$37,"" "",""☃"",LEN(Y$37)-LEN(SUBSTITUTE(Y$37,"" "",""""))))-1),Excepciones!$A:$B,2,0)>=0,IFERROR((INDEX(filter(Precios!$D:$D,(Precios!$A:$A<=$I10)*(Precios!$B:$B>=$I10)*(Precios!$C:$"&"C=Y$37)),1)*(1-$K$6)+VLOOKUP($L25,Precios!$F:$G,2,0)),""No asegurable""),""No asegurable"")),"""")"),"") | Z25: =IFERROR(__xludf.DUMMYFUNCTION("IFERROR(IF($I10="""","""",IF(VLOOKUP(LEFT(Z$37,SEARCH(""☃"",SUBSTITUTE(Z$37,"" "",""☃"",LEN(Z$37)-LEN(SUBSTITUTE(Z$37,"" "",""""))))-1),Excepciones!$A:$B,2,0)>=0,IFERROR(INDEX(filter(Precios!$D:$D,(Precios!$A:$A<=$I10)*(Precios!$B:$B>=$I10)*(Precios!$C:$C"&"=Z$37)),1)*(1-$K$6),""No asegurable""),""No asegurable"")),"""")"),"") | AA25: =IFERROR(__xludf.DUMMYFUNCTION("IFERROR(IF($I10="""","""",IF(VLOOKUP(LEFT(AA$37,SEARCH(""☃"",SUBSTITUTE(AA$37,"" "",""☃"",LEN(AA$37)-LEN(SUBSTITUTE(AA$37,"" "",""""))))-1),Excepciones!$A:$B,2,0)>=0,IFERROR(INDEX(filter(Precios!$D:$D,(Precios!$A:$A<=$I10)*(Precios!$B:$B>=$I10)*(Precios!$"&"C:$C=AA$37)),1)*(1-$K$6),""No asegurable""),""No asegurable"")),"""")"),"") | AB25: =IFERROR(__xludf.DUMMYFUNCTION("IFERROR(IF($I10="""","""",IF(VLOOKUP(LEFT(AB$37,SEARCH(""☃"",SUBSTITUTE(AB$37,"" "",""☃"",LEN(AB$37)-LEN(SUBSTITUTE(AB$37,"" "",""""))))-1),Excepciones!$A:$B,2,0)>=0,IFERROR(INDEX(filter(Precios!$D:$D,(Precios!$A:$A<=$I10)*(Precios!$B:$B>=$I10)*(Precios!$"&"C:$C=AB$37)),1)*(1-$K$6),""No asegurable""),""No asegurable"")),"""")"),"") | AC25: =IFERROR(__xludf.DUMMYFUNCTION("IFERROR(IF($I10="""","""",IF(VLOOKUP(LEFT(AC$37,SEARCH(""☃"",SUBSTITUTE(AC$37,"" "",""☃"",LEN(AC$37)-LEN(SUBSTITUTE(AC$37,"" "",""""))))-1),Excepciones!$A:$B,2,0)>=0,IFERROR(INDEX(filter(Precios!$D:$D,(Precios!$A:$A<=$I10)*(Precios!$B:$B>=$I10)*(Precios!$"&"C:$C=AC$37)),1)*(1-$K$6),""No asegurable""),""No asegurable"")),"""")"),"")
L26: 6 | N26: =N62 | O26: =IF(OR(O62="",O62=0),"",O62*(1-$K$8)) | Q26: =IF(OR(Q62="",Q62=0),"",Q62*(1-$K$8)) | R26: =IF(OR(R62="",R62=0),"",R62*(1-$K$8)) | T26: =IF(OR(T62="",T62=0),"",T62*(1-$K$8)) | U26: =IF(OR(U62="",U62=0),"",U62*(1-$K$8)) | W26: =IFERROR(__xludf.DUMMYFUNCTION("IFERROR(IF($I11="""","""",IF(VLOOKUP(LEFT(W$37,SEARCH(""☃"",SUBSTITUTE(W$37,"" "",""☃"",LEN(W$37)-LEN(SUBSTITUTE(W$37,"" "",""""))))-1),Excepciones!$A:$B,2,0)>=0,IFERROR(INDEX(filter(Precios!$D:$D,(Precios!$A:$A<=$I11)*(Precios!$B:$B>=$I11)*(Precios!$C:$C"&"=W$37)),1)*(1-$K$6),""No asegurable""),""No asegurable"")),"""")"),"") | Y26: =IFERROR(__xludf.DUMMYFUNCTION("IFERROR(IF($I11="""","""",IF(VLOOKUP(LEFT(Y$37,SEARCH(""☃"",SUBSTITUTE(Y$37,"" "",""☃"",LEN(Y$37)-LEN(SUBSTITUTE(Y$37,"" "",""""))))-1),Excepciones!$A:$B,2,0)>=0,IFERROR((INDEX(filter(Precios!$D:$D,(Precios!$A:$A<=$I11)*(Precios!$B:$B>=$I11)*(Precios!$C:$"&"C=Y$37)),1)*(1-$K$6)+VLOOKUP($L26,Precios!$F:$G,2,0)),""No asegurable""),""No asegurable"")),"""")"),"") | Z26: =IFERROR(__xludf.DUMMYFUNCTION("IFERROR(IF($I11="""","""",IF(VLOOKUP(LEFT(Z$37,SEARCH(""☃"",SUBSTITUTE(Z$37,"" "",""☃"",LEN(Z$37)-LEN(SUBSTITUTE(Z$37,"" "",""""))))-1),Excepciones!$A:$B,2,0)>=0,IFERROR(INDEX(filter(Precios!$D:$D,(Precios!$A:$A<=$I11)*(Precios!$B:$B>=$I11)*(Precios!$C:$C"&"=Z$37)),1)*(1-$K$6),""No asegurable""),""No asegurable"")),"""")"),"") | AA26: =IFERROR(__xludf.DUMMYFUNCTION("IFERROR(IF($I11="""","""",IF(VLOOKUP(LEFT(AA$37,SEARCH(""☃"",SUBSTITUTE(AA$37,"" "",""☃"",LEN(AA$37)-LEN(SUBSTITUTE(AA$37,"" "",""""))))-1),Excepciones!$A:$B,2,0)>=0,IFERROR(INDEX(filter(Precios!$D:$D,(Precios!$A:$A<=$I11)*(Precios!$B:$B>=$I11)*(Precios!$"&"C:$C=AA$37)),1)*(1-$K$6),""No asegurable""),""No asegurable"")),"""")"),"") | AB26: =IFERROR(__xludf.DUMMYFUNCTION("IFERROR(IF($I11="""","""",IF(VLOOKUP(LEFT(AB$37,SEARCH(""☃"",SUBSTITUTE(AB$37,"" "",""☃"",LEN(AB$37)-LEN(SUBSTITUTE(AB$37,"" "",""""))))-1),Excepciones!$A:$B,2,0)>=0,IFERROR(INDEX(filter(Precios!$D:$D,(Precios!$A:$A<=$I11)*(Precios!$B:$B>=$I11)*(Precios!$"&"C:$C=AB$37)),1)*(1-$K$6),""No asegurable""),""No asegurable"")),"""")"),"") | AC26: =IFERROR(__xludf.DUMMYFUNCTION("IFERROR(IF($I11="""","""",IF(VLOOKUP(LEFT(AC$37,SEARCH(""☃"",SUBSTITUTE(AC$37,"" "",""☃"",LEN(AC$37)-LEN(SUBSTITUTE(AC$37,"" "",""""))))-1),Excepciones!$A:$B,2,0)>=0,IFERROR(INDEX(filter(Precios!$D:$D,(Precios!$A:$A<=$I11)*(Precios!$B:$B>=$I11)*(Precios!$"&"C:$C=AC$37)),1)*(1-$K$6),""No asegurable""),""No asegurable"")),"""")"),"")
L27: 7 | N27: =N63 | O27: =IF(OR(O63="",O63=0),"",O63*(1-$K$8)) | Q27: =IF(OR(Q63="",Q63=0),"",Q63*(1-$K$8)) | R27: =IF(OR(R63="",R63=0),"",R63*(1-$K$8)) | T27: =IF(OR(T63="",T63=0),"",T63*(1-$K$8)) | U27: =IF(OR(U63="",U63=0),"",U63*(1-$K$8)) | W27: =IFERROR(__xludf.DUMMYFUNCTION("IFERROR(IF($I12="""","""",IF(VLOOKUP(LEFT(W$37,SEARCH(""☃"",SUBSTITUTE(W$37,"" "",""☃"",LEN(W$37)-LEN(SUBSTITUTE(W$37,"" "",""""))))-1),Excepciones!$A:$B,2,0)>=0,IFERROR(INDEX(filter(Precios!$D:$D,(Precios!$A:$A<=$I12)*(Precios!$B:$B>=$I12)*(Precios!$C:$C"&"=W$37)),1)*(1-$K$6),""No asegurable""),""No asegurable"")),"""")"),"") | Y27: =IFERROR(__xludf.DUMMYFUNCTION("IFERROR(IF($I12="""","""",IF(VLOOKUP(LEFT(Y$37,SEARCH(""☃"",SUBSTITUTE(Y$37,"" "",""☃"",LEN(Y$37)-LEN(SUBSTITUTE(Y$37,"" "",""""))))-1),Excepciones!$A:$B,2,0)>=0,IFERROR((INDEX(filter(Precios!$D:$D,(Precios!$A:$A<=$I12)*(Precios!$B:$B>=$I12)*(Precios!$C:$"&"C=Y$37)),1)*(1-$K$6)+VLOOKUP($L27,Precios!$F:$G,2,0)),""No asegurable""),""No asegurable"")),"""")"),"") | Z27: =IFERROR(__xludf.DUMMYFUNCTION("IFERROR(IF($I12="""","""",IF(VLOOKUP(LEFT(Z$37,SEARCH(""☃"",SUBSTITUTE(Z$37,"" "",""☃"",LEN(Z$37)-LEN(SUBSTITUTE(Z$37,"" "",""""))))-1),Excepciones!$A:$B,2,0)>=0,IFERROR(INDEX(filter(Precios!$D:$D,(Precios!$A:$A<=$I12)*(Precios!$B:$B>=$I12)*(Precios!$C:$C"&"=Z$37)),1)*(1-$K$6),""No asegurable""),""No asegurable"")),"""")"),"") | AA27: =IFERROR(__xludf.DUMMYFUNCTION("IFERROR(IF($I12="""","""",IF(VLOOKUP(LEFT(AA$37,SEARCH(""☃"",SUBSTITUTE(AA$37,"" "",""☃"",LEN(AA$37)-LEN(SUBSTITUTE(AA$37,"" "",""""))))-1),Excepciones!$A:$B,2,0)>=0,IFERROR(INDEX(filter(Precios!$D:$D,(Precios!$A:$A<=$I12)*(Precios!$B:$B>=$I12)*(Precios!$"&"C:$C=AA$37)),1)*(1-$K$6),""No asegurable""),""No asegurable"")),"""")"),"") | AB27: =IFERROR(__xludf.DUMMYFUNCTION("IFERROR(IF($I12="""","""",IF(VLOOKUP(LEFT(AB$37,SEARCH(""☃"",SUBSTITUTE(AB$37,"" "",""☃"",LEN(AB$37)-LEN(SUBSTITUTE(AB$37,"" "",""""))))-1),Excepciones!$A:$B,2,0)>=0,IFERROR(INDEX(filter(Precios!$D:$D,(Precios!$A:$A<=$I12)*(Precios!$B:$B>=$I12)*(Precios!$"&"C:$C=AB$37)),1)*(1-$K$6),""No asegurable""),""No asegurable"")),"""")"),"") | AC27: =IFERROR(__xludf.DUMMYFUNCTION("IFERROR(IF($I12="""","""",IF(VLOOKUP(LEFT(AC$37,SEARCH(""☃"",SUBSTITUTE(AC$37,"" "",""☃"",LEN(AC$37)-LEN(SUBSTITUTE(AC$37,"" "",""""))))-1),Excepciones!$A:$B,2,0)>=0,IFERROR(INDEX(filter(Precios!$D:$D,(Precios!$A:$A<=$I12)*(Precios!$B:$B>=$I12)*(Precios!$"&"C:$C=AC$37)),1)*(1-$K$6),""No asegurable""),""No asegurable"")),"""")"),"")
L28: 8 | N28: =N64 | O28: =IF(OR(O64="",O64=0),"",O64*(1-$K$8)) | Q28: =IF(OR(Q64="",Q64=0),"",Q64*(1-$K$8)) | R28: =IF(OR(R64="",R64=0),"",R64*(1-$K$8)) | T28: =IF(OR(T64="",T64=0),"",T64*(1-$K$8)) | U28: =IF(OR(U64="",U64=0),"",U64*(1-$K$8)) | W28: =IFERROR(__xludf.DUMMYFUNCTION("IFERROR(IF($I13="""","""",IF(VLOOKUP(LEFT(W$37,SEARCH(""☃"",SUBSTITUTE(W$37,"" "",""☃"",LEN(W$37)-LEN(SUBSTITUTE(W$37,"" "",""""))))-1),Excepciones!$A:$B,2,0)>=0,IFERROR(INDEX(filter(Precios!$D:$D,(Precios!$A:$A<=$I13)*(Precios!$B:$B>=$I13)*(Precios!$C:$C"&"=W$37)),1)*(1-$K$6),""No asegurable""),""No asegurable"")),"""")"),"") | Y28: =IFERROR(__xludf.DUMMYFUNCTION("IFERROR(IF($I13="""","""",IF(VLOOKUP(LEFT(Y$37,SEARCH(""☃"",SUBSTITUTE(Y$37,"" "",""☃"",LEN(Y$37)-LEN(SUBSTITUTE(Y$37,"" "",""""))))-1),Excepciones!$A:$B,2,0)>=0,IFERROR((INDEX(filter(Precios!$D:$D,(Precios!$A:$A<=$I13)*(Precios!$B:$B>=$I13)*(Precios!$C:$"&"C=Y$37)),1)*(1-$K$6)+VLOOKUP($L28,Precios!$F:$G,2,0)),""No asegurable""),""No asegurable"")),"""")"),"") | Z28: =IFERROR(__xludf.DUMMYFUNCTION("IFERROR(IF($I13="""","""",IF(VLOOKUP(LEFT(Z$37,SEARCH(""☃"",SUBSTITUTE(Z$37,"" "",""☃"",LEN(Z$37)-LEN(SUBSTITUTE(Z$37,"" "",""""))))-1),Excepciones!$A:$B,2,0)>=0,IFERROR(INDEX(filter(Precios!$D:$D,(Precios!$A:$A<=$I13)*(Precios!$B:$B>=$I13)*(Precios!$C:$C"&"=Z$37)),1)*(1-$K$6),""No asegurable""),""No asegurable"")),"""")"),"") | AA28: =IFERROR(__xludf.DUMMYFUNCTION("IFERROR(IF($I13="""","""",IF(VLOOKUP(LEFT(AA$37,SEARCH(""☃"",SUBSTITUTE(AA$37,"" "",""☃"",LEN(AA$37)-LEN(SUBSTITUTE(AA$37,"" "",""""))))-1),Excepciones!$A:$B,2,0)>=0,IFERROR(INDEX(filter(Precios!$D:$D,(Precios!$A:$A<=$I13)*(Precios!$B:$B>=$I13)*(Precios!$"&"C:$C=AA$37)),1)*(1-$K$6),""No asegurable""),""No asegurable"")),"""")"),"") | AB28: =IFERROR(__xludf.DUMMYFUNCTION("IFERROR(IF($I13="""","""",IF(VLOOKUP(LEFT(AB$37,SEARCH(""☃"",SUBSTITUTE(AB$37,"" "",""☃"",LEN(AB$37)-LEN(SUBSTITUTE(AB$37,"" "",""""))))-1),Excepciones!$A:$B,2,0)>=0,IFERROR(INDEX(filter(Precios!$D:$D,(Precios!$A:$A<=$I13)*(Precios!$B:$B>=$I13)*(Precios!$"&"C:$C=AB$37)),1)*(1-$K$6),""No asegurable""),""No asegurable"")),"""")"),"") | AC28: =IFERROR(__xludf.DUMMYFUNCTION("IFERROR(IF($I13="""","""",IF(VLOOKUP(LEFT(AC$37,SEARCH(""☃"",SUBSTITUTE(AC$37,"" "",""☃"",LEN(AC$37)-LEN(SUBSTITUTE(AC$37,"" "",""""))))-1),Excepciones!$A:$B,2,0)>=0,IFERROR(INDEX(filter(Precios!$D:$D,(Precios!$A:$A<=$I13)*(Precios!$B:$B>=$I13)*(Precios!$"&"C:$C=AC$37)),1)*(1-$K$6),""No asegurable""),""No asegurable"")),"""")"),"")
L29: 9 | N29: =N65 | O29: =IF(OR(O65="",O65=0),"",O65*(1-$K$8)) | Q29: =IF(OR(Q65="",Q65=0),"",Q65*(1-$K$8)) | R29: =IF(OR(R65="",R65=0),"",R65*(1-$K$8)) | T29: =IF(OR(T65="",T65=0),"",T65*(1-$K$8)) | U29: =IF(OR(U65="",U65=0),"",U65*(1-$K$8)) | W29: =IFERROR(__xludf.DUMMYFUNCTION("IFERROR(IF($I14="""","""",IF(VLOOKUP(LEFT(W$37,SEARCH(""☃"",SUBSTITUTE(W$37,"" "",""☃"",LEN(W$37)-LEN(SUBSTITUTE(W$37,"" "",""""))))-1),Excepciones!$A:$B,2,0)>=0,IFERROR(INDEX(filter(Precios!$D:$D,(Precios!$A:$A<=$I14)*(Precios!$B:$B>=$I14)*(Precios!$C:$C"&"=W$37)),1)*(1-$K$6),""No asegurable""),""No asegurable"")),"""")"),"") | Y29: =IFERROR(__xludf.DUMMYFUNCTION("IFERROR(IF($I14="""","""",IF(VLOOKUP(LEFT(Y$37,SEARCH(""☃"",SUBSTITUTE(Y$37,"" "",""☃"",LEN(Y$37)-LEN(SUBSTITUTE(Y$37,"" "",""""))))-1),Excepciones!$A:$B,2,0)>=0,IFERROR((INDEX(filter(Precios!$D:$D,(Precios!$A:$A<=$I14)*(Precios!$B:$B>=$I14)*(Precios!$C:$"&"C=Y$37)),1)*(1-$K$6)+VLOOKUP($L29,Precios!$F:$G,2,0)),""No asegurable""),""No asegurable"")),"""")"),"") | Z29: =IFERROR(__xludf.DUMMYFUNCTION("IFERROR(IF($I14="""","""",IF(VLOOKUP(LEFT(Z$37,SEARCH(""☃"",SUBSTITUTE(Z$37,"" "",""☃"",LEN(Z$37)-LEN(SUBSTITUTE(Z$37,"" "",""""))))-1),Excepciones!$A:$B,2,0)>=0,IFERROR(INDEX(filter(Precios!$D:$D,(Precios!$A:$A<=$I14)*(Precios!$B:$B>=$I14)*(Precios!$C:$C"&"=Z$37)),1)*(1-$K$6),""No asegurable""),""No asegurable"")),"""")"),"") | AA29: =IFERROR(__xludf.DUMMYFUNCTION("IFERROR(IF($I14="""","""",IF(VLOOKUP(LEFT(AA$37,SEARCH(""☃"",SUBSTITUTE(AA$37,"" "",""☃"",LEN(AA$37)-LEN(SUBSTITUTE(AA$37,"" "",""""))))-1),Excepciones!$A:$B,2,0)>=0,IFERROR(INDEX(filter(Precios!$D:$D,(Precios!$A:$A<=$I14)*(Precios!$B:$B>=$I14)*(Precios!$"&"C:$C=AA$37)),1)*(1-$K$6),""No asegurable""),""No asegurable"")),"""")"),"") | AB29: =IFERROR(__xludf.DUMMYFUNCTION("IFERROR(IF($I14="""","""",IF(VLOOKUP(LEFT(AB$37,SEARCH(""☃"",SUBSTITUTE(AB$37,"" "",""☃"",LEN(AB$37)-LEN(SUBSTITUTE(AB$37,"" "",""""))))-1),Excepciones!$A:$B,2,0)>=0,IFERROR(INDEX(filter(Precios!$D:$D,(Precios!$A:$A<=$I14)*(Precios!$B:$B>=$I14)*(Precios!$"&"C:$C=AB$37)),1)*(1-$K$6),""No asegurable""),""No asegurable"")),"""")"),"") | AC29: =IFERROR(__xludf.DUMMYFUNCTION("IFERROR(IF($I14="""","""",IF(VLOOKUP(LEFT(AC$37,SEARCH(""☃"",SUBSTITUTE(AC$37,"" "",""☃"",LEN(AC$37)-LEN(SUBSTITUTE(AC$37,"" "",""""))))-1),Excepciones!$A:$B,2,0)>=0,IFERROR(INDEX(filter(Precios!$D:$D,(Precios!$A:$A<=$I14)*(Precios!$B:$B>=$I14)*(Precios!$"&"C:$C=AC$37)),1)*(1-$K$6),""No asegurable""),""No asegurable"")),"""")"),"")
L30: 10 | N30: =N66 | O30: =IF(OR(O66="",O66=0),"",O66*(1-$K$8)) | Q30: =IF(OR(Q66="",Q66=0),"",Q66*(1-$K$8)) | R30: =IF(OR(R66="",R66=0),"",R66*(1-$K$8)) | T30: =IF(OR(T66="",T66=0),"",T66*(1-$K$8)) | U30: =IF(OR(U66="",U66=0),"",U66*(1-$K$8)) | W30: =IFERROR(__xludf.DUMMYFUNCTION("IFERROR(IF($I15="""","""",IF(VLOOKUP(LEFT(W$37,SEARCH(""☃"",SUBSTITUTE(W$37,"" "",""☃"",LEN(W$37)-LEN(SUBSTITUTE(W$37,"" "",""""))))-1),Excepciones!$A:$B,2,0)>=0,IFERROR(INDEX(filter(Precios!$D:$D,(Precios!$A:$A<=$I15)*(Precios!$B:$B>=$I15)*(Precios!$C:$C"&"=W$37)),1)*(1-$K$6),""No asegurable""),""No asegurable"")),"""")"),"") | Y30: =IFERROR(__xludf.DUMMYFUNCTION("IFERROR(IF($I15="""","""",IF(VLOOKUP(LEFT(Y$37,SEARCH(""☃"",SUBSTITUTE(Y$37,"" "",""☃"",LEN(Y$37)-LEN(SUBSTITUTE(Y$37,"" "",""""))))-1),Excepciones!$A:$B,2,0)>=0,IFERROR((INDEX(filter(Precios!$D:$D,(Precios!$A:$A<=$I15)*(Precios!$B:$B>=$I15)*(Precios!$C:$"&"C=Y$37)),1)*(1-$K$6)+VLOOKUP($L30,Precios!$F:$G,2,0)),""No asegurable""),""No asegurable"")),"""")"),"") | Z30: =IFERROR(__xludf.DUMMYFUNCTION("IFERROR(IF($I15="""","""",IF(VLOOKUP(LEFT(Z$37,SEARCH(""☃"",SUBSTITUTE(Z$37,"" "",""☃"",LEN(Z$37)-LEN(SUBSTITUTE(Z$37,"" "",""""))))-1),Excepciones!$A:$B,2,0)>=0,IFERROR(INDEX(filter(Precios!$D:$D,(Precios!$A:$A<=$I15)*(Precios!$B:$B>=$I15)*(Precios!$C:$C"&"=Z$37)),1)*(1-$K$6),""No asegurable""),""No asegurable"")),"""")"),"") | AA30: =IFERROR(__xludf.DUMMYFUNCTION("IFERROR(IF($I15="""","""",IF(VLOOKUP(LEFT(AA$37,SEARCH(""☃"",SUBSTITUTE(AA$37,"" "",""☃"",LEN(AA$37)-LEN(SUBSTITUTE(AA$37,"" "",""""))))-1),Excepciones!$A:$B,2,0)>=0,IFERROR(INDEX(filter(Precios!$D:$D,(Precios!$A:$A<=$I15)*(Precios!$B:$B>=$I15)*(Precios!$"&"C:$C=AA$37)),1)*(1-$K$6),""No asegurable""),""No asegurable"")),"""")"),"") | AB30: =IFERROR(__xludf.DUMMYFUNCTION("IFERROR(IF($I15="""","""",IF(VLOOKUP(LEFT(AB$37,SEARCH(""☃"",SUBSTITUTE(AB$37,"" "",""☃"",LEN(AB$37)-LEN(SUBSTITUTE(AB$37,"" "",""""))))-1),Excepciones!$A:$B,2,0)>=0,IFERROR(INDEX(filter(Precios!$D:$D,(Precios!$A:$A<=$I15)*(Precios!$B:$B>=$I15)*(Precios!$"&"C:$C=AB$37)),1)*(1-$K$6),""No asegurable""),""No asegurable"")),"""")"),"") | AC30: =IFERROR(__xludf.DUMMYFUNCTION("IFERROR(IF($I15="""","""",IF(VLOOKUP(LEFT(AC$37,SEARCH(""☃"",SUBSTITUTE(AC$37,"" "",""☃"",LEN(AC$37)-LEN(SUBSTITUTE(AC$37,"" "",""""))))-1),Excepciones!$A:$B,2,0)>=0,IFERROR(INDEX(filter(Precios!$D:$D,(Precios!$A:$A<=$I15)*(Precios!$B:$B>=$I15)*(Precios!$"&"C:$C=AC$37)),1)*(1-$K$6),""No asegurable""),""No asegurable"")),"""")"),"")
L31: 11 | N31: =N67 | O31: =IF(OR(O67="",O67=0),"",O67*(1-$K$8)) | Q31: =IF(OR(Q67="",Q67=0),"",Q67*(1-$K$8)) | R31: =IF(OR(R67="",R67=0),"",R67*(1-$K$8)) | T31: =IF(OR(T67="",T67=0),"",T67*(1-$K$8)) | U31: =IF(OR(U67="",U67=0),"",U67*(1-$K$8)) | W31: =IFERROR(__xludf.DUMMYFUNCTION("IFERROR(IF($I16="""","""",IF(VLOOKUP(LEFT(W$37,SEARCH(""☃"",SUBSTITUTE(W$37,"" "",""☃"",LEN(W$37)-LEN(SUBSTITUTE(W$37,"" "",""""))))-1),Excepciones!$A:$B,2,0)>=0,IFERROR(INDEX(filter(Precios!$D:$D,(Precios!$A:$A<=$I16)*(Precios!$B:$B>=$I16)*(Precios!$C:$C"&"=W$37)),1)*(1-$K$6),""No asegurable""),""No asegurable"")),"""")"),"") | Y31: =IFERROR(__xludf.DUMMYFUNCTION("IFERROR(IF($I16="""","""",IF(VLOOKUP(LEFT(Y$37,SEARCH(""☃"",SUBSTITUTE(Y$37,"" "",""☃"",LEN(Y$37)-LEN(SUBSTITUTE(Y$37,"" "",""""))))-1),Excepciones!$A:$B,2,0)>=0,IFERROR((INDEX(filter(Precios!$D:$D,(Precios!$A:$A<=$I16)*(Precios!$B:$B>=$I16)*(Precios!$C:$"&"C=Y$37)),1)*(1-$K$6)+VLOOKUP($L31,Precios!$F:$G,2,0)),""No asegurable""),""No asegurable"")),"""")"),"") | Z31: =IFERROR(__xludf.DUMMYFUNCTION("IFERROR(IF($I16="""","""",IF(VLOOKUP(LEFT(Z$37,SEARCH(""☃"",SUBSTITUTE(Z$37,"" "",""☃"",LEN(Z$37)-LEN(SUBSTITUTE(Z$37,"" "",""""))))-1),Excepciones!$A:$B,2,0)>=0,IFERROR(INDEX(filter(Precios!$D:$D,(Precios!$A:$A<=$I16)*(Precios!$B:$B>=$I16)*(Precios!$C:$C"&"=Z$37)),1)*(1-$K$6),""No asegurable""),""No asegurable"")),"""")"),"") | AA31: =IFERROR(__xludf.DUMMYFUNCTION("IFERROR(IF($I16="""","""",IF(VLOOKUP(LEFT(AA$37,SEARCH(""☃"",SUBSTITUTE(AA$37,"" "",""☃"",LEN(AA$37)-LEN(SUBSTITUTE(AA$37,"" "",""""))))-1),Excepciones!$A:$B,2,0)>=0,IFERROR(INDEX(filter(Precios!$D:$D,(Precios!$A:$A<=$I16)*(Precios!$B:$B>=$I16)*(Precios!$"&"C:$C=AA$37)),1)*(1-$K$6),""No asegurable""),""No asegurable"")),"""")"),"") | AB31: =IFERROR(__xludf.DUMMYFUNCTION("IFERROR(IF($I16="""","""",IF(VLOOKUP(LEFT(AB$37,SEARCH(""☃"",SUBSTITUTE(AB$37,"" "",""☃"",LEN(AB$37)-LEN(SUBSTITUTE(AB$37,"" "",""""))))-1),Excepciones!$A:$B,2,0)>=0,IFERROR(INDEX(filter(Precios!$D:$D,(Precios!$A:$A<=$I16)*(Precios!$B:$B>=$I16)*(Precios!$"&"C:$C=AB$37)),1)*(1-$K$6),""No asegurable""),""No asegurable"")),"""")"),"") | AC31: =IFERROR(__xludf.DUMMYFUNCTION("IFERROR(IF($I16="""","""",IF(VLOOKUP(LEFT(AC$37,SEARCH(""☃"",SUBSTITUTE(AC$37,"" "",""☃"",LEN(AC$37)-LEN(SUBSTITUTE(AC$37,"" "",""""))))-1),Excepciones!$A:$B,2,0)>=0,IFERROR(INDEX(filter(Precios!$D:$D,(Precios!$A:$A<=$I16)*(Precios!$B:$B>=$I16)*(Precios!$"&"C:$C=AC$37)),1)*(1-$K$6),""No asegurable""),""No asegurable"")),"""")"),"")
L32: 12 | N32: =N68 | O32: =IF(OR(O68="",O68=0),"",O68*(1-$K$8)) | Q32: =IF(OR(Q68="",Q68=0),"",Q68*(1-$K$8)) | R32: =IF(OR(R68="",R68=0),"",R68*(1-$K$8)) | T32: =IF(OR(T68="",T68=0),"",T68*(1-$K$8)) | U32: =IF(OR(U68="",U68=0),"",U68*(1-$K$8)) | W32: =IFERROR(__xludf.DUMMYFUNCTION("IFERROR(IF($I17="""","""",IF(VLOOKUP(LEFT(W$37,SEARCH(""☃"",SUBSTITUTE(W$37,"" "",""☃"",LEN(W$37)-LEN(SUBSTITUTE(W$37,"" "",""""))))-1),Excepciones!$A:$B,2,0)>=0,IFERROR(INDEX(filter(Precios!$D:$D,(Precios!$A:$A<=$I17)*(Precios!$B:$B>=$I17)*(Precios!$C:$C"&"=W$37)),1)*(1-$K$6),""No asegurable""),""No asegurable"")),"""")"),"") | Y32: =IFERROR(__xludf.DUMMYFUNCTION("IFERROR(IF($I17="""","""",IF(VLOOKUP(LEFT(Y$37,SEARCH(""☃"",SUBSTITUTE(Y$37,"" "",""☃"",LEN(Y$37)-LEN(SUBSTITUTE(Y$37,"" "",""""))))-1),Excepciones!$A:$B,2,0)>=0,IFERROR((INDEX(filter(Precios!$D:$D,(Precios!$A:$A<=$I17)*(Precios!$B:$B>=$I17)*(Precios!$C:$"&"C=Y$37)),1)*(1-$K$6)+VLOOKUP($L32,Precios!$F:$G,2,0)),""No asegurable""),""No asegurable"")),"""")"),"") | Z32: =IFERROR(__xludf.DUMMYFUNCTION("IFERROR(IF($I17="""","""",IF(VLOOKUP(LEFT(Z$37,SEARCH(""☃"",SUBSTITUTE(Z$37,"" "",""☃"",LEN(Z$37)-LEN(SUBSTITUTE(Z$37,"" "",""""))))-1),Excepciones!$A:$B,2,0)>=0,IFERROR(INDEX(filter(Precios!$D:$D,(Precios!$A:$A<=$I17)*(Precios!$B:$B>=$I17)*(Precios!$C:$C"&"=Z$37)),1)*(1-$K$6),""No asegurable""),""No asegurable"")),"""")"),"") | AA32: =IFERROR(__xludf.DUMMYFUNCTION("IFERROR(IF($I17="""","""",IF(VLOOKUP(LEFT(AA$37,SEARCH(""☃"",SUBSTITUTE(AA$37,"" "",""☃"",LEN(AA$37)-LEN(SUBSTITUTE(AA$37,"" "",""""))))-1),Excepciones!$A:$B,2,0)>=0,IFERROR(INDEX(filter(Precios!$D:$D,(Precios!$A:$A<=$I17)*(Precios!$B:$B>=$I17)*(Precios!$"&"C:$C=AA$37)),1)*(1-$K$6),""No asegurable""),""No asegurable"")),"""")"),"") | AB32: =IFERROR(__xludf.DUMMYFUNCTION("IFERROR(IF($I17="""","""",IF(VLOOKUP(LEFT(AB$37,SEARCH(""☃"",SUBSTITUTE(AB$37,"" "",""☃"",LEN(AB$37)-LEN(SUBSTITUTE(AB$37,"" "",""""))))-1),Excepciones!$A:$B,2,0)>=0,IFERROR(INDEX(filter(Precios!$D:$D,(Precios!$A:$A<=$I17)*(Precios!$B:$B>=$I17)*(Precios!$"&"C:$C=AB$37)),1)*(1-$K$6),""No asegurable""),""No asegurable"")),"""")"),"") | AC32: =IFERROR(__xludf.DUMMYFUNCTION("IFERROR(IF($I17="""","""",IF(VLOOKUP(LEFT(AC$37,SEARCH(""☃"",SUBSTITUTE(AC$37,"" "",""☃"",LEN(AC$37)-LEN(SUBSTITUTE(AC$37,"" "",""""))))-1),Excepciones!$A:$B,2,0)>=0,IFERROR(INDEX(filter(Precios!$D:$D,(Precios!$A:$A<=$I17)*(Precios!$B:$B>=$I17)*(Precios!$"&"C:$C=AC$37)),1)*(1-$K$6),""No asegurable""),""No asegurable"")),"""")"),"")
L33: 13 | N33: =N69 | O33: =IF(OR(O69="",O69=0),"",O69*(1-$K$8)) | Q33: =IF(OR(Q69="",Q69=0),"",Q69*(1-$K$8)) | R33: =IF(OR(R69="",R69=0),"",R69*(1-$K$8)) | T33: =IF(OR(T69="",T69=0),"",T69*(1-$K$8)) | U33: =IF(OR(U69="",U69=0),"",U69*(1-$K$8)) | W33: =IFERROR(__xludf.DUMMYFUNCTION("IFERROR(IF($I18="""","""",IF(VLOOKUP(LEFT(W$37,SEARCH(""☃"",SUBSTITUTE(W$37,"" "",""☃"",LEN(W$37)-LEN(SUBSTITUTE(W$37,"" "",""""))))-1),Excepciones!$A:$B,2,0)>=0,IFERROR(INDEX(filter(Precios!$D:$D,(Precios!$A:$A<=$I18)*(Precios!$B:$B>=$I18)*(Precios!$C:$C"&"=W$37)),1)*(1-$K$6),""No asegurable""),""No asegurable"")),"""")"),"") | Y33: =IFERROR(__xludf.DUMMYFUNCTION("IFERROR(IF($I18="""","""",IF(VLOOKUP(LEFT(Y$37,SEARCH(""☃"",SUBSTITUTE(Y$37,"" "",""☃"",LEN(Y$37)-LEN(SUBSTITUTE(Y$37,"" "",""""))))-1),Excepciones!$A:$B,2,0)>=0,IFERROR((INDEX(filter(Precios!$D:$D,(Precios!$A:$A<=$I18)*(Precios!$B:$B>=$I18)*(Precios!$C:$"&"C=Y$37)),1)*(1-$K$6)+VLOOKUP($L33,Precios!$F:$G,2,0)),""No asegurable""),""No asegurable"")),"""")"),"") | Z33: =IFERROR(__xludf.DUMMYFUNCTION("IFERROR(IF($I18="""","""",IF(VLOOKUP(LEFT(Z$37,SEARCH(""☃"",SUBSTITUTE(Z$37,"" "",""☃"",LEN(Z$37)-LEN(SUBSTITUTE(Z$37,"" "",""""))))-1),Excepciones!$A:$B,2,0)>=0,IFERROR(INDEX(filter(Precios!$D:$D,(Precios!$A:$A<=$I18)*(Precios!$B:$B>=$I18)*(Precios!$C:$C"&"=Z$37)),1)*(1-$K$6),""No asegurable""),""No asegurable"")),"""")"),"") | AA33: =IFERROR(__xludf.DUMMYFUNCTION("IFERROR(IF($I18="""","""",IF(VLOOKUP(LEFT(AA$37,SEARCH(""☃"",SUBSTITUTE(AA$37,"" "",""☃"",LEN(AA$37)-LEN(SUBSTITUTE(AA$37,"" "",""""))))-1),Excepciones!$A:$B,2,0)>=0,IFERROR(INDEX(filter(Precios!$D:$D,(Precios!$A:$A<=$I18)*(Precios!$B:$B>=$I18)*(Precios!$"&"C:$C=AA$37)),1)*(1-$K$6),""No asegurable""),""No asegurable"")),"""")"),"") | AB33: =IFERROR(__xludf.DUMMYFUNCTION("IFERROR(IF($I18="""","""",IF(VLOOKUP(LEFT(AB$37,SEARCH(""☃"",SUBSTITUTE(AB$37,"" "",""☃"",LEN(AB$37)-LEN(SUBSTITUTE(AB$37,"" "",""""))))-1),Excepciones!$A:$B,2,0)>=0,IFERROR(INDEX(filter(Precios!$D:$D,(Precios!$A:$A<=$I18)*(Precios!$B:$B>=$I18)*(Precios!$"&"C:$C=AB$37)),1)*(1-$K$6),""No asegurable""),""No asegurable"")),"""")"),"") | AC33: =IFERROR(__xludf.DUMMYFUNCTION("IFERROR(IF($I18="""","""",IF(VLOOKUP(LEFT(AC$37,SEARCH(""☃"",SUBSTITUTE(AC$37,"" "",""☃"",LEN(AC$37)-LEN(SUBSTITUTE(AC$37,"" "",""""))))-1),Excepciones!$A:$B,2,0)>=0,IFERROR(INDEX(filter(Precios!$D:$D,(Precios!$A:$A<=$I18)*(Precios!$B:$B>=$I18)*(Precios!$"&"C:$C=AC$37)),1)*(1-$K$6),""No asegurable""),""No asegurable"")),"""")"),"")
L34: 14 | N34: =N70 | O34: =IF(OR(O70="",O70=0),"",O70*(1-$K$8)) | Q34: =IF(OR(Q70="",Q70=0),"",Q70*(1-$K$8)) | R34: =IF(OR(R70="",R70=0),"",R70*(1-$K$8)) | T34: =IF(OR(T70="",T70=0),"",T70*(1-$K$8)) | U34: =IF(OR(U70="",U70=0),"",U70*(1-$K$8)) | W34: =IFERROR(__xludf.DUMMYFUNCTION("IFERROR(IF($I19="""","""",IF(VLOOKUP(LEFT(W$37,SEARCH(""☃"",SUBSTITUTE(W$37,"" "",""☃"",LEN(W$37)-LEN(SUBSTITUTE(W$37,"" "",""""))))-1),Excepciones!$A:$B,2,0)>=0,IFERROR(INDEX(filter(Precios!$D:$D,(Precios!$A:$A<=$I19)*(Precios!$B:$B>=$I19)*(Precios!$C:$C"&"=W$37)),1)*(1-$K$6),""No asegurable""),""No asegurable"")),"""")"),"") | Y34: =IFERROR(__xludf.DUMMYFUNCTION("IFERROR(IF($I19="""","""",IF(VLOOKUP(LEFT(Y$37,SEARCH(""☃"",SUBSTITUTE(Y$37,"" "",""☃"",LEN(Y$37)-LEN(SUBSTITUTE(Y$37,"" "",""""))))-1),Excepciones!$A:$B,2,0)>=0,IFERROR((INDEX(filter(Precios!$D:$D,(Precios!$A:$A<=$I19)*(Precios!$B:$B>=$I19)*(Precios!$C:$"&"C=Y$37)),1)*(1-$K$6)+VLOOKUP($L34,Precios!$F:$G,2,0)),""No asegurable""),""No asegurable"")),"""")"),"") | Z34: =IFERROR(__xludf.DUMMYFUNCTION("IFERROR(IF($I19="""","""",IF(VLOOKUP(LEFT(Z$37,SEARCH(""☃"",SUBSTITUTE(Z$37,"" "",""☃"",LEN(Z$37)-LEN(SUBSTITUTE(Z$37,"" "",""""))))-1),Excepciones!$A:$B,2,0)>=0,IFERROR(INDEX(filter(Precios!$D:$D,(Precios!$A:$A<=$I19)*(Precios!$B:$B>=$I19)*(Precios!$C:$C"&"=Z$37)),1)*(1-$K$6),""No asegurable""),""No asegurable"")),"""")"),"") | AA34: =IFERROR(__xludf.DUMMYFUNCTION("IFERROR(IF($I19="""","""",IF(VLOOKUP(LEFT(AA$37,SEARCH(""☃"",SUBSTITUTE(AA$37,"" "",""☃"",LEN(AA$37)-LEN(SUBSTITUTE(AA$37,"" "",""""))))-1),Excepciones!$A:$B,2,0)>=0,IFERROR(INDEX(filter(Precios!$D:$D,(Precios!$A:$A<=$I19)*(Precios!$B:$B>=$I19)*(Precios!$"&"C:$C=AA$37)),1)*(1-$K$6),""No asegurable""),""No asegurable"")),"""")"),"") | AB34: =IFERROR(__xludf.DUMMYFUNCTION("IFERROR(IF($I19="""","""",IF(VLOOKUP(LEFT(AB$37,SEARCH(""☃"",SUBSTITUTE(AB$37,"" "",""☃"",LEN(AB$37)-LEN(SUBSTITUTE(AB$37,"" "",""""))))-1),Excepciones!$A:$B,2,0)>=0,IFERROR(INDEX(filter(Precios!$D:$D,(Precios!$A:$A<=$I19)*(Precios!$B:$B>=$I19)*(Precios!$"&"C:$C=AB$37)),1)*(1-$K$6),""No asegurable""),""No asegurable"")),"""")"),"") | AC34: =IFERROR(__xludf.DUMMYFUNCTION("IFERROR(IF($I19="""","""",IF(VLOOKUP(LEFT(AC$37,SEARCH(""☃"",SUBSTITUTE(AC$37,"" "",""☃"",LEN(AC$37)-LEN(SUBSTITUTE(AC$37,"" "",""""))))-1),Excepciones!$A:$B,2,0)>=0,IFERROR(INDEX(filter(Precios!$D:$D,(Precios!$A:$A<=$I19)*(Precios!$B:$B>=$I19)*(Precios!$"&"C:$C=AC$37)),1)*(1-$K$6),""No asegurable""),""No asegurable"")),"""")"),"")
L35: 15 | N35: =N71 | O35: =IF(OR(O71="",O71=0),"",O71*(1-$K$8)) | Q35: =IF(OR(Q71="",Q71=0),"",Q71*(1-$K$8)) | R35: =IF(OR(R71="",R71=0),"",R71*(1-$K$8)) | T35: =IF(OR(T71="",T71=0),"",T71*(1-$K$8)) | U35: =IF(OR(U71="",U71=0),"",U71*(1-$K$8)) | W35: =IFERROR(__xludf.DUMMYFUNCTION("IFERROR(IF($I20="""","""",IF(VLOOKUP(LEFT(W$37,SEARCH(""☃"",SUBSTITUTE(W$37,"" "",""☃"",LEN(W$37)-LEN(SUBSTITUTE(W$37,"" "",""""))))-1),Excepciones!$A:$B,2,0)>=0,IFERROR(INDEX(filter(Precios!$D:$D,(Precios!$A:$A<=$I20)*(Precios!$B:$B>=$I20)*(Precios!$C:$C"&"=W$37)),1)*(1-$K$6),""No asegurable""),""No asegurable"")),"""")"),"") | Y35: =IFERROR(__xludf.DUMMYFUNCTION("IFERROR(IF($I20="""","""",IF(VLOOKUP(LEFT(Y$37,SEARCH(""☃"",SUBSTITUTE(Y$37,"" "",""☃"",LEN(Y$37)-LEN(SUBSTITUTE(Y$37,"" "",""""))))-1),Excepciones!$A:$B,2,0)>=0,IFERROR((INDEX(filter(Precios!$D:$D,(Precios!$A:$A<=$I20)*(Precios!$B:$B>=$I20)*(Precios!$C:$"&"C=Y$37)),1)*(1-$K$6)+VLOOKUP($L35,Precios!$F:$G,2,0)),""No asegurable""),""No asegurable"")),"""")"),"") | Z35: =IFERROR(__xludf.DUMMYFUNCTION("IFERROR(IF($I20="""","""",IF(VLOOKUP(LEFT(Z$37,SEARCH(""☃"",SUBSTITUTE(Z$37,"" "",""☃"",LEN(Z$37)-LEN(SUBSTITUTE(Z$37,"" "",""""))))-1),Excepciones!$A:$B,2,0)>=0,IFERROR(INDEX(filter(Precios!$D:$D,(Precios!$A:$A<=$I20)*(Precios!$B:$B>=$I20)*(Precios!$C:$C"&"=Z$37)),1)*(1-$K$6),""No asegurable""),""No asegurable"")),"""")"),"") | AA35: =IFERROR(__xludf.DUMMYFUNCTION("IFERROR(IF($I20="""","""",IF(VLOOKUP(LEFT(AA$37,SEARCH(""☃"",SUBSTITUTE(AA$37,"" "",""☃"",LEN(AA$37)-LEN(SUBSTITUTE(AA$37,"" "",""""))))-1),Excepciones!$A:$B,2,0)>=0,IFERROR(INDEX(filter(Precios!$D:$D,(Precios!$A:$A<=$I20)*(Precios!$B:$B>=$I20)*(Precios!$"&"C:$C=AA$37)),1)*(1-$K$6),""No asegurable""),""No asegurable"")),"""")"),"") | AB35: =IFERROR(__xludf.DUMMYFUNCTION("IFERROR(IF($I20="""","""",IF(VLOOKUP(LEFT(AB$37,SEARCH(""☃"",SUBSTITUTE(AB$37,"" "",""☃"",LEN(AB$37)-LEN(SUBSTITUTE(AB$37,"" "",""""))))-1),Excepciones!$A:$B,2,0)>=0,IFERROR(INDEX(filter(Precios!$D:$D,(Precios!$A:$A<=$I20)*(Precios!$B:$B>=$I20)*(Precios!$"&"C:$C=AB$37)),1)*(1-$K$6),""No asegurable""),""No asegurable"")),"""")"),"") | AC35: =IFERROR(__xludf.DUMMYFUNCTION("IFERROR(IF($I20="""","""",IF(VLOOKUP(LEFT(AC$37,SEARCH(""☃"",SUBSTITUTE(AC$37,"" "",""☃"",LEN(AC$37)-LEN(SUBSTITUTE(AC$37,"" "",""""))))-1),Excepciones!$A:$B,2,0)>=0,IFERROR(INDEX(filter(Precios!$D:$D,(Precios!$A:$A<=$I20)*(Precios!$B:$B>=$I20)*(Precios!$"&"C:$C=AC$37)),1)*(1-$K$6),""No asegurable""),""No asegurable"")),"""")"),"")
L37: CON DENTAL | N37: ="Go"&" "&$K$3 -> Go 2 | O37: ="Plena Vital"&" "&$K$3 -> Plena Vital 2 | P37: ="Plena Total vital"&" "&$K$3 -> Plena Total vital 2 | Q37: ="Plena"&" "&$K$3 -> Plena 2 | R37: ="Plena Plus"&" "&$K$3 -> Plena Plus 2 | S37: ="Plena Total"&" "&$K$3 -> Plena Total 2 | T37: ="Plena Extra 150"&" "&$K$3 -> Plena Extra 150 2 | U37: ="Seniors"&" "&$K$3 -> Seniors 2 | V37: ="Seniors total"&" "&$K$3 -> Seniors total 2 | W37: ="Negocios NIF"&" "&$K$3 -> Negocios NIF 2 | X37: ="Pymes TOTAL"&" "&$K$3 -> Pymes TOTAL 2 | Y37: =IF(OR(COUNT(I6:I13)=1,COUNT(I6:I13)=2),"Extra Negocios NIF"&" "&$K$3&" "&COUNT(I6:I13),"Extra Negocios NIF"&" "&$K$3) -> Extra Negocios NIF 2 | Z37: ="Negocios CIF"&" "&$K$3 -> Negocios CIF 2 | AA37: ="Extra Negocios CIF"&" "&$K$3 -> Extra Negocios CIF 2 | AB37: ="Empresas"&" "&$K$3 -> Empresas 2 | AC37: ="Extra Empresas"&" "&$K$3 -> Extra Empresas 2
L39: 1 | N39: =N75 -> 23.8125 | O39: =IF(OR(O75="",O75=0),"",O75*(1-$K$8)) -> 49.9125 | P39: =IF(OR(P75="",P75=0),"",P75*(1-$K$8)) -> 54.9 | Q39: =IF(OR(Q75="",Q75=0),"",Q75*(1-$K$8)) -> 60.2625 | R39: =IF(OR(R75="",R75=0),"",R75*(1-$K$8)) -> 71.9625 | S39: =IF(OR(S75="",S75=0),"",S75*(1-$K$8)) -> 92.7 | T39: =IF(OR(T75="",T75=0),"",T75*(1-$K$8)) -> 114.4625 | U39: =IF(OR(U75="",U75=0),"",U75*(1-$K$8)) | V39: =IF(OR(V75="",V75=0),"",V75*(1-$K$8)) | W39: =IFERROR(__xludf.DUMMYFUNCTION("IFERROR(IF($I6="""","""",IF(VLOOKUP(LEFT(W$37,SEARCH(""☃"",SUBSTITUTE(W$37,"" "",""☃"",LEN(W$37)-LEN(SUBSTITUTE(W$37,"" "",""""))))-1),Excepciones!$A:$B,2,0)>=0,IFERROR((INDEX(filter(Precios!$D:$D,(Precios!$A:$A<=$I6)*(Precios!$B:$B>=$I6)*(Precios!$C:$C=W"&"$37)),1)*(1-$K$6)+VLOOKUP(COUNT($I$6:$I$13),Precios!$F:$G,2,0)),""No asegurable""),""No asegurable"")),"""")"),67.9625) -> 67.9625 | X39: =IF(OR($K$10="Sí",X75=""),"",IF($K$8>0,X75*(1-($K$8)*2),X75)) -> 62 | Y39: =IFERROR(__xludf.DUMMYFUNCTION("IFERROR(IF($I6="""","""",IF(VLOOKUP(LEFT(Y$37,SEARCH(""☃"",SUBSTITUTE(Y$37,"" "",""☃"",LEN(Y$37)-LEN(SUBSTITUTE(Y$37,"" "",""""))))-1),Excepciones!$A:$B,2,0)>=0,IFERROR(INDEX(filter(Precios!$D:$D,(Precios!$A:$A<=$I6)*(Precios!$B:$B>=$I6)*(Precios!$C:$C=Y$"&"37)),1)*(1-$K$6),""No asegurable""),""No asegurable"")),"""")"),"")
L40: 2 | N40: =N76 -> 23.8125 | O40: =IF(OR(O76="",O76=0),"",O76*(1-$K$8)) -> 49.9125 | P40: =IF(OR(P76="",P76=0),"",P76*(1-$K$8)) -> 54.9 | Q40: =IF(OR(Q76="",Q76=0),"",Q76*(1-$K$8)) -> 60.2625 | R40: =IF(OR(R76="",R76=0),"",R76*(1-$K$8)) -> 71.9625 | S40: =IF(OR(S76="",S76=0),"",S76*(1-$K$8)) -> 92.7 | T40: =IF(OR(T76="",T76=0),"",T76*(1-$K$8)) -> 114.4625 | U40: =IF(OR(U76="",U76=0),"",U76*(1-$K$8)) | V40: =IF(OR(V76="",V76=0),"",V76*(1-$K$8)) | W40: =IFERROR(__xludf.DUMMYFUNCTION("IFERROR(IF($I7="""","""",IF(VLOOKUP(LEFT(W$37,SEARCH(""☃"",SUBSTITUTE(W$37,"" "",""☃"",LEN(W$37)-LEN(SUBSTITUTE(W$37,"" "",""""))))-1),Excepciones!$A:$B,2,0)>=0,IFERROR((INDEX(filter(Precios!$D:$D,(Precios!$A:$A<=$I7)*(Precios!$B:$B>=$I7)*(Precios!$C:$C=W"&"$37)),1)*(1-$K$6)+VLOOKUP(COUNT($I$6:$I$13),Precios!$F:$G,2,0)),""No asegurable""),""No asegurable"")),"""")"),67.9625) -> 67.9625 | X40: =IF(OR($K$10="Sí",X76=""),"",IF($K$8>0,X76*(1-($K$8)*2),X76)) -> 62 | Y40: =IFERROR(__xludf.DUMMYFUNCTION("IFERROR(IF($I7="""","""",IF(VLOOKUP(LEFT(Y$37,SEARCH(""☃"",SUBSTITUTE(Y$37,"" "",""☃"",LEN(Y$37)-LEN(SUBSTITUTE(Y$37,"" "",""""))))-1),Excepciones!$A:$B,2,0)>=0,IFERROR(INDEX(filter(Precios!$D:$D,(Precios!$A:$A<=$I7)*(Precios!$B:$B>=$I7)*(Precios!$C:$C=Y$"&"37)),1)*(1-$K$6),""No asegurable""),""No asegurable"")),"""")"),"")
